Workbook

Sheet 요약 및 분석
B1: ○ [FC사업부] 걸개처별 매출 추이 — 요약 및 분석
B2: 기준: 주간 '25.08.18 ~ '26.10.18 (61주) / 월간 2026년 1~9월 · 출처: FC사업부 Weekly Brand Tracking(261019) · 금액 단위: 백만원(셀 값은 원)
B4: 1. 핵심 지표
B5: 최근주 매출 (10/12~10/18) | E5: ='주별 매출'!BM5 -> 5010739067 | G5: 전주 대비 | J5: ='주별 매출'!BM5/'주별 매출'!BL5-1 -> -0.019555398
B6: 전년 동주 대비 | E6: ='주별 매출'!BM5/'주별 매출'!M5-1 -> 0.24146351 | G6: 최근 4주 매출 | J6: ='걸개처별 추이 요약'!M8 -> 19961978700
B7: 4주 증감률 (직전 4주 대비) | E7: ='걸개처별 추이 요약'!O8 -> -0.031377513 | G7: 9월 매출 | J7: ='월별 매출'!L5 -> 21340213998
B8: 9월 전월 대비 | E8: ='월별 매출'!U5 -> -0.062675873 | G8: 1~9월 누계 매출 | J8: ='월별 매출'!M5 -> 196906636099
B9: 1Q→3Q 월평균 증감률 | E9: ='걸개처별 추이 요약'!H8 -> 0.090428802 | G9: 상위 5개 걸개처 매출 비중 (최근 4주) | J9: =SUM('걸개처별 추이 요약'!R9:R13) -> 0.54300356
B11: 2. 월별 전체 매출 추이 (백만원)
B12: 구분 | D12: 1월 | E12: 2월 | F12: 3월 | G12: 4월 | H12: 5월 | I12: 6월 | J12: 7월 | K12: 8월 | L12: 9월
B13: 월 매출 | D13: ='월별 매출'!D5 -> 21750286263 | E13: ='월별 매출'!E5 -> 19295447144 | F13: ='월별 매출'!F5 -> 20923415382 | G13: ='월별 매출'!G5 -> 21599349179 | H13: ='월별 매출'!H5 -> 23431970830 | I13: ='월별 매출'!I5 -> 22333222631 | J13: ='월별 매출'!J5 -> 23465564667 | K13: ='월별 매출'!K5 -> 22767166005 | L13: ='월별 매출'!L5 -> 21340213998
B14: 전월 대비 | D14: - | E14: ='월별 매출'!N5 -> -0.11286468 | F14: ='월별 매출'!O5 -> 0.084370589 | G14: ='월별 매출'!P5 -> 0.032305137 | H14: ='월별 매출'!Q5 -> 0.084846151 | I14: ='월별 매출'!R5 -> -0.046890985 | J14: ='월별 매출'!S5 -> 0.050702134 | K14: ='월별 매출'!T5 -> -0.029762704 | L14: ='월별 매출'!U5 -> -0.062675873
B16: 3. 걸개처 추세 분포 (걸개처 수)
B17: 구분 | D17: ▲ 상승 | E17: ― 보합 | F17: ▼ 하락 | G17: ● 신규 발생 | H17: ■ 매출 중단
B18: 단기 (최근 4주 vs 직전 4주) | D18: =COUNTIF('걸개처별 추이 요약'!S9:S128,"▲*") -> 16 | E18: =COUNTIF('걸개처별 추이 요약'!S9:S128,"―*") -> 21 | F18: =COUNTIF('걸개처별 추이 요약'!S9:S128,"▼*") -> 55 | G18: =COUNTIF('걸개처별 추이 요약'!S9:S128,"●*") -> 1 | H18: =COUNTIF('걸개처별 추이 요약'!S9:S128,"■*") -> 3
B19: 장기 (1~3월 vs 7~9월 월평균) | D19: =COUNTIF('걸개처별 추이 요약'!T9:T128,"▲*") -> 29 | E19: =COUNTIF('걸개처별 추이 요약'!T9:T128,"―*") -> 15 | F19: =COUNTIF('걸개처별 추이 요약'!T9:T128,"▼*") -> 41 | G19: =COUNTIF('걸개처별 추이 요약'!T9:T128,"●*") -> 14 | H19: =COUNTIF('걸개처별 추이 요약'!T9:T128,"■*") -> 13
B20: ※ 증감률 ±5% 이상을 상승·하락으로 판정. 기간 내 매출이 없는 걸개처는 집계 제외.
B22: 4. 주요 분석
B23: 전체 흐름 | D23: 월 매출은 7월(234.7억)을 고점으로 8월 -3.0%, 9월 -6.3% 두 달 연속 감소. 다만 최근주 매출은 전년 동주 대비 +24%로 연간 성장세는 유지.
B24: 매출 집중도 | D24: 역전할머니맥주 1곳이 최근 4주 매출의 약 32%, 상위 5개 걸개처가 약 54%를 차지. 상위 걸개처 변동이 전체 실적을 좌우하는 구조.
B25: 성장 견인 | D25: 준코(신규, 월평균 5억→18억), 차얌·88핫도그(+76%), 숯토리(+64%), 경성맥주(+44%), 디케이푸드(+41%), 쥬씨(+30%)가 1Q 대비 3Q 성장을 견인.
B26: 구조적 하락 | D26: 미스앤미스터(-23%), 형제푸드(-21%), 함께그린(-17%), 서래식구들(-17%), 쓰리비플러스(-15%), 메이크어딜리버리(-12%), 킹콩(-11%)은 1Q 대비 3Q 월평균 감소. 메이크어딜리버리는 단기도 하락 지속.
B27: 단기 급감 | D27: 척척밥상(-29%), 오백국수(-17%), 디케이푸드(-17%), 치킨플러스(-13%)가 최근 4주 큰 폭 감소. 척척밥상은 9/21주 급감(0.45억) 후 회복 중.
B28: 신규 안착 | D28: 버거앤타코(8월 말 첫 매출 후 주 0.3억→0.5억), 콩시루(+22%), 후참잘(+10%)이 빠르게 매출 확대 중.
B29: 해석 주의 | D29: 지미존스·감자마켓 등은 주간 매출에 큰 음수(정산/차감 추정)가 있어 주간 증감률이 왜곡됨. 최근 4주에 추석 연휴 주(9/21~27)가 포함됨. → 5. 확인 필요 사항 참조
B30: ※ 본문 수치는 작성 시점(10/19) 데이터 기준 해석이며, 아래 표와 다른 시트의 수치는 수식으로 연동됨.
B32: 4-1. 주목할 걸개처 (수치는 요약 시트 연동)
C33: 구분 | D33: 본점명 | E33: 최근 4주 매출 | F33: 4주 증감률 | G33: 9월 매출 | H33: 9월 전월 대비 | I33: 1Q→3Q 증감률 | J33: 전년 동주 대비 | K33: 단기 추세 | L33: 장기 추세
C34: 장기 성장 | D34: 준코 대분류 | E34: =IFERROR(INDEX('걸개처별 추이 요약'!$M$9:$M$128,MATCH($D34,'걸개처별 추이 요약'!$D$9:$D$128,0)),"") -> 1741354296 | F34: =IFERROR(INDEX('걸개처별 추이 요약'!$O$9:$O$128,MATCH($D34,'걸개처별 추이 요약'!$D$9:$D$128,0)),"") -> 0.075191116 | G34: =IFERROR(INDEX('걸개처별 추이 요약'!$I$9:$I$128,MATCH($D34,'걸개처별 추이 요약'!$D$9:$D$128,0)),"") -> 1836670965 | H34: =IFERROR(INDEX('걸개처별 추이 요약'!$J$9:$J$128,MATCH($D34,'걸개처별 추이 요약'!$D$9:$D$128,0)),"") -> 0.018135291 | I34: =IFERROR(INDEX('걸개처별 추이 요약'!$H$9:$H$128,MATCH($D34,'걸개처별 추이 요약'!$D$9:$D$128,0)),"") -> 2.4454067 | J34: =IFERROR(INDEX('걸개처별 추이 요약'!$Q$9:$Q$128,MATCH($D34,'걸개처별 추이 요약'!$D$9:$D$128,0)),"") | K34: =IFERROR(INDEX('걸개처별 추이 요약'!$S$9:$S$128,MATCH($D34,'걸개처별 추이 요약'!$D$9:$D$128,0)),"") -> ▲ 상승 | L34: =IFERROR(INDEX('걸개처별 추이 요약'!$T$9:$T$128,MATCH($D34,'걸개처별 추이 요약'!$D$9:$D$128,0)),"") -> ▲ 상승
C35: 장기 성장 | D35: (유)가로수브랜딩_숯토리(대) | E35: =IFERROR(INDEX('걸개처별 추이 요약'!$M$9:$M$128,MATCH($D35,'걸개처별 추이 요약'!$D$9:$D$128,0)),"") -> 479753758 | F35: =IFERROR(INDEX('걸개처별 추이 요약'!$O$9:$O$128,MATCH($D35,'걸개처별 추이 요약'!$D$9:$D$128,0)),"") -> 0.076313365 | G35: =IFERROR(INDEX('걸개처별 추이 요약'!$I$9:$I$128,MATCH($D35,'걸개처별 추이 요약'!$D$9:$D$128,0)),"") -> 509432352 | H35: =IFERROR(INDEX('걸개처별 추이 요약'!$J$9:$J$128,MATCH($D35,'걸개처별 추이 요약'!$D$9:$D$128,0)),"") -> 0.066908304 | I35: =IFERROR(INDEX('걸개처별 추이 요약'!$H$9:$H$128,MATCH($D35,'걸개처별 추이 요약'!$D$9:$D$128,0)),"") -> 0.63644232 | J35: =IFERROR(INDEX('걸개처별 추이 요약'!$Q$9:$Q$128,MATCH($D35,'걸개처별 추이 요약'!$D$9:$D$128,0)),"") -> 1.1984789 | K35: =IFERROR(INDEX('걸개처별 추이 요약'!$S$9:$S$128,MATCH($D35,'걸개처별 추이 요약'!$D$9:$D$128,0)),"") -> ▲ 상승 | L35: =IFERROR(INDEX('걸개처별 추이 요약'!$T$9:$T$128,MATCH($D35,'걸개처별 추이 요약'!$D$9:$D$128,0)),"") -> ▲ 상승
C36: 장기 성장 | D36: 차얌,88핫도그_주식회사 프로젝트비_대분류 | E36: =IFERROR(INDEX('걸개처별 추이 요약'!$M$9:$M$128,MATCH($D36,'걸개처별 추이 요약'!$D$9:$D$128,0)),"") -> 150160541 | F36: =IFERROR(INDEX('걸개처별 추이 요약'!$O$9:$O$128,MATCH($D36,'걸개처별 추이 요약'!$D$9:$D$128,0)),"") -> -0.10708545 | G36: =IFERROR(INDEX('걸개처별 추이 요약'!$I$9:$I$128,MATCH($D36,'걸개처별 추이 요약'!$D$9:$D$128,0)),"") -> 178729832 | H36: =IFERROR(INDEX('걸개처별 추이 요약'!$J$9:$J$128,MATCH($D36,'걸개처별 추이 요약'!$D$9:$D$128,0)),"") -> -0.10606761 | I36: =IFERROR(INDEX('걸개처별 추이 요약'!$H$9:$H$128,MATCH($D36,'걸개처별 추이 요약'!$D$9:$D$128,0)),"") -> 0.76000305 | J36: =IFERROR(INDEX('걸개처별 추이 요약'!$Q$9:$Q$128,MATCH($D36,'걸개처별 추이 요약'!$D$9:$D$128,0)),"") -> -0.1474521 | K36: =IFERROR(INDEX('걸개처별 추이 요약'!$S$9:$S$128,MATCH($D36,'걸개처별 추이 요약'!$D$9:$D$128,0)),"") -> ▼ 하락 | L36: =IFERROR(INDEX('걸개처별 추이 요약'!$T$9:$T$128,MATCH($D36,'걸개처별 추이 요약'!$D$9:$D$128,0)),"") -> ▲ 상승
C37: 장기 성장 | D37: 경성맥주_대분류 | E37: =IFERROR(INDEX('걸개처별 추이 요약'!$M$9:$M$128,MATCH($D37,'걸개처별 추이 요약'!$D$9:$D$128,0)),"") -> 114330574 | F37: =IFERROR(INDEX('걸개처별 추이 요약'!$O$9:$O$128,MATCH($D37,'걸개처별 추이 요약'!$D$9:$D$128,0)),"") -> -0.074047176 | G37: =IFERROR(INDEX('걸개처별 추이 요약'!$I$9:$I$128,MATCH($D37,'걸개처별 추이 요약'!$D$9:$D$128,0)),"") -> 134444334 | H37: =IFERROR(INDEX('걸개처별 추이 요약'!$J$9:$J$128,MATCH($D37,'걸개처별 추이 요약'!$D$9:$D$128,0)),"") -> -0.11000045 | I37: =IFERROR(INDEX('걸개처별 추이 요약'!$H$9:$H$128,MATCH($D37,'걸개처별 추이 요약'!$D$9:$D$128,0)),"") -> 0.44256386 | J37: =IFERROR(INDEX('걸개처별 추이 요약'!$Q$9:$Q$128,MATCH($D37,'걸개처별 추이 요약'!$D$9:$D$128,0)),"") -> -0.084683624 | K37: =IFERROR(INDEX('걸개처별 추이 요약'!$S$9:$S$128,MATCH($D37,'걸개처별 추이 요약'!$D$9:$D$128,0)),"") -> ▼ 하락 | L37: =IFERROR(INDEX('걸개처별 추이 요약'!$T$9:$T$128,MATCH($D37,'걸개처별 추이 요약'!$D$9:$D$128,0)),"") -> ▲ 상승
C38: 신규 안착 | D38: 버거앤타코 | E38: =IFERROR(INDEX('걸개처별 추이 요약'!$M$9:$M$128,MATCH($D38,'걸개처별 추이 요약'!$D$9:$D$128,0)),"") -> 181559154 | F38: =IFERROR(INDEX('걸개처별 추이 요약'!$O$9:$O$128,MATCH($D38,'걸개처별 추이 요약'!$D$9:$D$128,0)),"") -> 5.3082639 | G38: =IFERROR(INDEX('걸개처별 추이 요약'!$I$9:$I$128,MATCH($D38,'걸개처별 추이 요약'!$D$9:$D$128,0)),"") -> 88518594 | H38: =IFERROR(INDEX('걸개처별 추이 요약'!$J$9:$J$128,MATCH($D38,'걸개처별 추이 요약'!$D$9:$D$128,0)),"") | I38: =IFERROR(INDEX('걸개처별 추이 요약'!$H$9:$H$128,MATCH($D38,'걸개처별 추이 요약'!$D$9:$D$128,0)),"") | J38: =IFERROR(INDEX('걸개처별 추이 요약'!$Q$9:$Q$128,MATCH($D38,'걸개처별 추이 요약'!$D$9:$D$128,0)),"") | K38: =IFERROR(INDEX('걸개처별 추이 요약'!$S$9:$S$128,MATCH($D38,'걸개처별 추이 요약'!$D$9:$D$128,0)),"") -> ▲ 상승 | L38: =IFERROR(INDEX('걸개처별 추이 요약'!$T$9:$T$128,MATCH($D38,'걸개처별 추이 요약'!$D$9:$D$128,0)),"") -> ● 신규 발생
C39: 장기 하락 | D39: FR_미스앤미스터 | E39: =IFERROR(INDEX('걸개처별 추이 요약'!$M$9:$M$128,MATCH($D39,'걸개처별 추이 요약'!$D$9:$D$128,0)),"") -> 646136281 | F39: =IFERROR(INDEX('걸개처별 추이 요약'!$O$9:$O$128,MATCH($D39,'걸개처별 추이 요약'!$D$9:$D$128,0)),"") -> 0.10191636 | G39: =IFERROR(INDEX('걸개처별 추이 요약'!$I$9:$I$128,MATCH($D39,'걸개처별 추이 요약'!$D$9:$D$128,0)),"") -> 648818993 | H39: =IFERROR(INDEX('걸개처별 추이 요약'!$J$9:$J$128,MATCH($D39,'걸개처별 추이 요약'!$D$9:$D$128,0)),"") -> 0.096185311 | I39: =IFERROR(INDEX('걸개처별 추이 요약'!$H$9:$H$128,MATCH($D39,'걸개처별 추이 요약'!$D$9:$D$128,0)),"") -> -0.22764203 | J39: =IFERROR(INDEX('걸개처별 추이 요약'!$Q$9:$Q$128,MATCH($D39,'걸개처별 추이 요약'!$D$9:$D$128,0)),"") -> -0.21419699 | K39: =IFERROR(INDEX('걸개처별 추이 요약'!$S$9:$S$128,MATCH($D39,'걸개처별 추이 요약'!$D$9:$D$128,0)),"") -> ▲ 상승 | L39: =IFERROR(INDEX('걸개처별 추이 요약'!$T$9:$T$128,MATCH($D39,'걸개처별 추이 요약'!$D$9:$D$128,0)),"") -> ▼ 하락
C40: 장기 하락 | D40: 메이크어딜리버리 대분류 | E40: =IFERROR(INDEX('걸개처별 추이 요약'!$M$9:$M$128,MATCH($D40,'걸개처별 추이 요약'!$D$9:$D$128,0)),"") -> 387374987 | F40: =IFERROR(INDEX('걸개처별 추이 요약'!$O$9:$O$128,MATCH($D40,'걸개처별 추이 요약'!$D$9:$D$128,0)),"") -> -0.056011633 | G40: =IFERROR(INDEX('걸개처별 추이 요약'!$I$9:$I$128,MATCH($D40,'걸개처별 추이 요약'!$D$9:$D$128,0)),"") -> 418767227 | H40: =IFERROR(INDEX('걸개처별 추이 요약'!$J$9:$J$128,MATCH($D40,'걸개처별 추이 요약'!$D$9:$D$128,0)),"") -> -0.17493845 | I40: =IFERROR(INDEX('걸개처별 추이 요약'!$H$9:$H$128,MATCH($D40,'걸개처별 추이 요약'!$D$9:$D$128,0)),"") -> -0.11739802 | J40: =IFERROR(INDEX('걸개처별 추이 요약'!$Q$9:$Q$128,MATCH($D40,'걸개처별 추이 요약'!$D$9:$D$128,0)),"") -> -0.2830737 | K40: =IFERROR(INDEX('걸개처별 추이 요약'!$S$9:$S$128,MATCH($D40,'걸개처별 추이 요약'!$D$9:$D$128,0)),"") -> ▼ 하락 | L40: =IFERROR(INDEX('걸개처별 추이 요약'!$T$9:$T$128,MATCH($D40,'걸개처별 추이 요약'!$D$9:$D$128,0)),"") -> ▼ 하락
C41: 장기 하락 | D41: 함께그린 대코드 | E41: =IFERROR(INDEX('걸개처별 추이 요약'!$M$9:$M$128,MATCH($D41,'걸개처별 추이 요약'!$D$9:$D$128,0)),"") -> 189562578 | F41: =IFERROR(INDEX('걸개처별 추이 요약'!$O$9:$O$128,MATCH($D41,'걸개처별 추이 요약'!$D$9:$D$128,0)),"") -> -0.056491331 | G41: =IFERROR(INDEX('걸개처별 추이 요약'!$I$9:$I$128,MATCH($D41,'걸개처별 추이 요약'!$D$9:$D$128,0)),"") -> 225175374 | H41: =IFERROR(INDEX('걸개처별 추이 요약'!$J$9:$J$128,MATCH($D41,'걸개처별 추이 요약'!$D$9:$D$128,0)),"") -> 0.043796826 | I41: =IFERROR(INDEX('걸개처별 추이 요약'!$H$9:$H$128,MATCH($D41,'걸개처별 추이 요약'!$D$9:$D$128,0)),"") -> -0.17184775 | J41: =IFERROR(INDEX('걸개처별 추이 요약'!$Q$9:$Q$128,MATCH($D41,'걸개처별 추이 요약'!$D$9:$D$128,0)),"") -> -0.43987854 | K41: =IFERROR(INDEX('걸개처별 추이 요약'!$S$9:$S$128,MATCH($D41,'걸개처별 추이 요약'!$D$9:$D$128,0)),"") -> ▼ 하락 | L41: =IFERROR(INDEX('걸개처별 추이 요약'!$T$9:$T$128,MATCH($D41,'걸개처별 추이 요약'!$D$9:$D$128,0)),"") -> ▼ 하락
C42: 장기 하락 | D42: 형제푸드 대코드 | E42: =IFERROR(INDEX('걸개처별 추이 요약'!$M$9:$M$128,MATCH($D42,'걸개처별 추이 요약'!$D$9:$D$128,0)),"") -> 56761865 | F42: =IFERROR(INDEX('걸개처별 추이 요약'!$O$9:$O$128,MATCH($D42,'걸개처별 추이 요약'!$D$9:$D$128,0)),"") -> -0.076494674 | G42: =IFERROR(INDEX('걸개처별 추이 요약'!$I$9:$I$128,MATCH($D42,'걸개처별 추이 요약'!$D$9:$D$128,0)),"") -> 63846025 | H42: =IFERROR(INDEX('걸개처별 추이 요약'!$J$9:$J$128,MATCH($D42,'걸개처별 추이 요약'!$D$9:$D$128,0)),"") -> -0.050528135 | I42: =IFERROR(INDEX('걸개처별 추이 요약'!$H$9:$H$128,MATCH($D42,'걸개처별 추이 요약'!$D$9:$D$128,0)),"") -> -0.207713 | J42: =IFERROR(INDEX('걸개처별 추이 요약'!$Q$9:$Q$128,MATCH($D42,'걸개처별 추이 요약'!$D$9:$D$128,0)),"") -> -0.29841667 | K42: =IFERROR(INDEX('걸개처별 추이 요약'!$S$9:$S$128,MATCH($D42,'걸개처별 추이 요약'!$D$9:$D$128,0)),"") -> ▼ 하락 | L42: =IFERROR(INDEX('걸개처별 추이 요약'!$T$9:$T$128,MATCH($D42,'걸개처별 추이 요약'!$D$9:$D$128,0)),"") -> ▼ 하락
C43: 단기 급감 | D43: 척척밥상 대코드 | E43: =IFERROR(INDEX('걸개처별 추이 요약'!$M$9:$M$128,MATCH($D43,'걸개처별 추이 요약'!$D$9:$D$128,0)),"") -> 908748440 | F43: =IFERROR(INDEX('걸개처별 추이 요약'!$O$9:$O$128,MATCH($D43,'걸개처별 추이 요약'!$D$9:$D$128,0)),"") -> -0.29353638 | G43: =IFERROR(INDEX('걸개처별 추이 요약'!$I$9:$I$128,MATCH($D43,'걸개처별 추이 요약'!$D$9:$D$128,0)),"") -> 1095470420 | H43: =IFERROR(INDEX('걸개처별 추이 요약'!$J$9:$J$128,MATCH($D43,'걸개처별 추이 요약'!$D$9:$D$128,0)),"") -> -0.15963276 | I43: =IFERROR(INDEX('걸개처별 추이 요약'!$H$9:$H$128,MATCH($D43,'걸개처별 추이 요약'!$D$9:$D$128,0)),"") -> 0.044576032 | J43: =IFERROR(INDEX('걸개처별 추이 요약'!$Q$9:$Q$128,MATCH($D43,'걸개처별 추이 요약'!$D$9:$D$128,0)),"") -> 0.034034 | K43: =IFERROR(INDEX('걸개처별 추이 요약'!$S$9:$S$128,MATCH($D43,'걸개처별 추이 요약'!$D$9:$D$128,0)),"") -> ▼ 하락 | L43: =IFERROR(INDEX('걸개처별 추이 요약'!$T$9:$T$128,MATCH($D43,'걸개처별 추이 요약'!$D$9:$D$128,0)),"") -> ― 보합
C44: 최대 비중 | D44: 역전할머니맥주 대 | E44: =IFERROR(INDEX('걸개처별 추이 요약'!$M$9:$M$128,MATCH($D44,'걸개처별 추이 요약'!$D$9:$D$128,0)),"") -> 6465640601 | F44: =IFERROR(INDEX('걸개처별 추이 요약'!$O$9:$O$128,MATCH($D44,'걸개처별 추이 요약'!$D$9:$D$128,0)),"") -> 0.0078801012 | G44: =IFERROR(INDEX('걸개처별 추이 요약'!$I$9:$I$128,MATCH($D44,'걸개처별 추이 요약'!$D$9:$D$128,0)),"") -> 7100651508 | H44: =IFERROR(INDEX('걸개처별 추이 요약'!$J$9:$J$128,MATCH($D44,'걸개처별 추이 요약'!$D$9:$D$128,0)),"") -> -0.066199697 | I44: =IFERROR(INDEX('걸개처별 추이 요약'!$H$9:$H$128,MATCH($D44,'걸개처별 추이 요약'!$D$9:$D$128,0)),"") -> 0.11388597 | J44: =IFERROR(INDEX('걸개처별 추이 요약'!$Q$9:$Q$128,MATCH($D44,'걸개처별 추이 요약'!$D$9:$D$128,0)),"") -> 0.31815919 | K44: =IFERROR(INDEX('걸개처별 추이 요약'!$S$9:$S$128,MATCH($D44,'걸개처별 추이 요약'!$D$9:$D$128,0)),"") -> ― 보합 | L44: =IFERROR(INDEX('걸개처별 추이 요약'!$T$9:$T$128,MATCH($D44,'걸개처별 추이 요약'!$D$9:$D$128,0)),"") -> ▲ 상승
B47: 5. 확인 필요 사항
...

Sheet 걸개처별 추이 요약
A1: ○ [FC사업부] 걸개처별 매출 추이 요약
A2: 기준: 최근주 2026.10.12~10.18 / 월간 2026.1~9월 · 금액 단위 백만원(셀 값은 원 단위) · 추세 기준: 증감률 ±5% 이상 상승·하락, 그 사이 보합
B3: 최근주 전체 매출 | D3: 전주 대비 | F3: 전년 동주 대비 | H3: 9월 전월 대비 | J3: 단기 상승 걸개처 수 | L3: 단기 하락 걸개처 수
B4: ='주별 매출'!BM5 -> 5010739067 | D4: ='주별 매출'!BM5/'주별 매출'!BL5-1 -> -0.019555398 | F4: ='주별 매출'!BM5/'주별 매출'!M5-1 -> 0.24146351 | H4: ='월별 매출'!U5 -> -0.062675873 | J4: =COUNTIF(S9:S500,"▲*") -> 16 | L4: =COUNTIF(S9:S500,"▼*") -> 55
F6: 월간 추이 (Monthly) | K6: 주간 추이 (Weekly)
A7: 순위 | B7: 구분 | C7: 본점코드 | D7: 본점명 | E7: 매장수 (최근주) | F7: 1Q 월평균 (1~3월) | G7: 3Q 월평균 (7~9월) | H7: 1Q→3Q 증감률 | I7: 9월 매출 | J7: 9월 전월 대비 | K7: 최근주 매출 | L7: 전주 대비 | M7: 최근 4주 매출 | N7: 직전 4주 매출 | O7: 4주 증감률 | P7: 전년 동주 매출 | Q7: 전년 동주 대비 | R7: 최근 4주 매출 비중 | S7: 단기 추세 (4주) | T7: 장기 추세 (1Q→3Q) | U7: 비고
B8: 전체 | D8: 합계 (120개 걸개처) | E8: ='주별 매출'!D5 -> 3976 | F8: =AVERAGE('월별 매출'!D5:F5) -> 2.0656383e+10 | G8: =AVERAGE('월별 매출'!J5:L5) -> 22524314890 | H8: =IF(F8=0,"",G8/F8-1) -> 0.090428802 | I8: ='월별 매출'!L5 -> 21340213998 | J8: ='월별 매출'!U5 -> -0.062675873 | K8: ='주별 매출'!BM5 -> 5010739067 | L8: =IF('주별 매출'!BL5=0,"",K8/'주별 매출'!BL5-1) -> -0.019555398 | M8: =SUM('주별 매출'!BJ5:BM5) -> 19961978700 | N8: =SUM('주별 매출'!BF5:BI5) -> 20608626137 | O8: =IF(N8=0,"",M8/N8-1) -> -0.031377513 | P8: ='주별 매출'!M5 -> 4036154931 | Q8: =IF(P8=0,"",K8/P8-1) -> 0.24146351 | R8: =IF($M$8=0,"",M8/$M$8) -> 1 | S8: =IF(AND(M8=0,N8=0),"-",IF(N8=0,"-",IF(M8=0,"■ 매출 중단",IF(O8>=0.05,"▲ 상승",IF(O8<=-0.05,"▼ 하락","― 보합"))))) -> ― 보합 | T8: =IF(AND(F8=0,G8=0),"-",IF(F8=0,"-",IF(G8=0,"■ 매출 중단",IF(H8>=0.05,"▲ 상승",IF(H8<=-0.05,"▼ 하락","― 보합"))))) -> ▲ 상승 | U8: 후참잘·샤브온당은 월간 코드 차이로 월간 합계에 일부만 포함
A9: 1 | B9: 기존 | C9: S82657 | D9: 역전할머니맥주 대 | E9: ='주별 매출'!D81 -> 970 | F9: =AVERAGE('월별 매출'!D81:F81) -> 6711224359 | G9: =AVERAGE('월별 매출'!J81:L81) -> 7475538636 | H9: =IF(F9=0,"",G9/F9-1) -> 0.11388597 | I9: ='월별 매출'!L81 -> 7100651508 | J9: ='월별 매출'!U81 -> -0.066199697 | K9: ='주별 매출'!BM81 -> 1540682457 | L9: =IF('주별 매출'!BL81=0,"",K9/'주별 매출'!BL81-1) -> -0.022711307 | M9: =SUM('주별 매출'!BJ81:BM81) -> 6465640601 | N9: =SUM('주별 매출'!BF81:BI81) -> 6415089050 | O9: =IF(N9=0,"",M9/N9-1) -> 0.0078801012 | P9: ='주별 매출'!M81 -> 1168813651 | Q9: =IF(P9=0,"",K9/P9-1) -> 0.31815919 | R9: =IF($M$8=0,"",M9/$M$8) -> 0.32389778 | S9: =IF(AND(M9=0,N9=0),"-",IF(N9=0,"● 신규 발생",IF(M9=0,"■ 매출 중단",IF(O9>=0.05,"▲ 상승",IF(O9<=-0.05,"▼ 하락","― 보합"))))) -> ― 보합 | T9: =IF(AND(F9=0,G9=0),"-",IF(F9=0,"● 신규 발생",IF(G9=0,"■ 매출 중단",IF(H9>=0.05,"▲ 상승",IF(H9<=-0.05,"▼ 하락","― 보합"))))) -> ▲ 상승
A10: 2 | B10: 신규 | C10: S90525 | D10: 준코 대분류 | E10: ='주별 매출'!D11 -> 136 | F10: =AVERAGE('월별 매출'!D11:F11) -> 5.2434492e+08 | G10: =AVERAGE('월별 매출'!J11:L11) -> 1.8065815e+09 | H10: =IF(F10=0,"",G10/F10-1) -> 2.4454067 | I10: ='월별 매출'!L11 -> 1836670965 | J10: ='월별 매출'!U11 -> 0.018135291 | K10: ='주별 매출'!BM11 -> 381044155 | L10: =IF('주별 매출'!BL11=0,"",K10/'주별 매출'!BL11-1) -> -0.1246303 | M10: =SUM('주별 매출'!BJ11:BM11) -> 1741354296 | N10: =SUM('주별 매출'!BF11:BI11) -> 1619576529 | O10: =IF(N10=0,"",M10/N10-1) -> 0.075191116 | P10: ='주별 매출'!M11 -> 0 | Q10: =IF(P10=0,"",K10/P10-1) | R10: =IF($M$8=0,"",M10/$M$8) -> 0.087233551 | S10: =IF(AND(M10=0,N10=0),"-",IF(N10=0,"● 신규 발생",IF(M10=0,"■ 매출 중단",IF(O10>=0.05,"▲ 상승",IF(O10<=-0.05,"▼ 하락","― 보합"))))) -> ▲ 상승 | T10: =IF(AND(F10=0,G10=0),"-",IF(F10=0,"● 신규 발생",IF(G10=0,"■ 매출 중단",IF(H10>=0.05,"▲ 상승",IF(H10<=-0.05,"▼ 하락","― 보합"))))) -> ▲ 상승
A11: 3 | B11: 기존 | C11: S81737 | D11: 족발야시장_대분류 (무청감자탕 통합) | E11: ='주별 매출'!D79 -> 196 | F11: =AVERAGE('월별 매출'!D79:F79) -> 1.096716e+09 | G11: =AVERAGE('월별 매출'!J79:L79) -> 1.0608767e+09 | H11: =IF(F11=0,"",G11/F11-1) -> -0.032678792 | I11: ='월별 매출'!L79 -> 1033837396 | J11: ='월별 매출'!U79 -> -0.035304407 | K11: ='주별 매출'!BM79 -> 223985928 | L11: =IF('주별 매출'!BL79=0,"",K11/'주별 매출'!BL79-1) -> -0.051835623 | M11: =SUM('주별 매출'!BJ79:BM79) -> 914475895 | N11: =SUM('주별 매출'!BF79:BI79) -> 967116026 | O11: =IF(N11=0,"",M11/N11-1) -> -0.054430006 | P11: ='주별 매출'!M79 -> 269882111 | Q11: =IF(P11=0,"",K11/P11-1) -> -0.17006012 | R11: =IF($M$8=0,"",M11/$M$8) -> 0.045810884 | S11: =IF(AND(M11=0,N11=0),"-",IF(N11=0,"● 신규 발생",IF(M11=0,"■ 매출 중단",IF(O11>=0.05,"▲ 상승",IF(O11<=-0.05,"▼ 하락","― 보합"))))) -> ▼ 하락 | T11: =IF(AND(F11=0,G11=0),"-",IF(F11=0,"● 신규 발생",IF(G11=0,"■ 매출 중단",IF(H11>=0.05,"▲ 상승",IF(H11<=-0.05,"▼ 하락","― 보합"))))) -> ― 보합
A12: 4 | B12: 기존 | C12: S233197 | D12: 척척밥상 대코드 | E12: ='주별 매출'!D51 -> 32 | F12: =AVERAGE('월별 매출'!D51:F51) -> 1.2515318e+09 | G12: =AVERAGE('월별 매출'!J51:L51) -> 1.3073202e+09 | H12: =IF(F12=0,"",G12/F12-1) -> 0.044576032 | I12: ='월별 매출'!L51 -> 1095470420 | J12: ='월별 매출'!U51 -> -0.15963276 | K12: ='주별 매출'!BM51 -> 317159870 | L12: =IF('주별 매출'!BL51=0,"",K12/'주별 매출'!BL51-1) -> 0.046081154 | M12: =SUM('주별 매출'!BJ51:BM51) -> 908748440 | N12: =SUM('주별 매출'!BF51:BI51) -> 1286334370 | O12: =IF(N12=0,"",M12/N12-1) -> -0.29353638 | P12: ='주별 매출'!M51 -> 306720930 | Q12: =IF(P12=0,"",K12/P12-1) -> 0.034034 | R12: =IF($M$8=0,"",M12/$M$8) -> 0.045523966 | S12: =IF(AND(M12=0,N12=0),"-",IF(N12=0,"● 신규 발생",IF(M12=0,"■ 매출 중단",IF(O12>=0.05,"▲ 상승",IF(O12<=-0.05,"▼ 하락","― 보합"))))) -> ▼ 하락 | T12: =IF(AND(F12=0,G12=0),"-",IF(F12=0,"● 신규 발생",IF(G12=0,"■ 매출 중단",IF(H12>=0.05,"▲ 상승",IF(H12<=-0.05,"▼ 하락","― 보합"))))) -> ― 보합
A13: 5 | B13: 기존 | C13: S215014 | D13: 아이센스 (대) | E13: ='주별 매출'!D32 -> 289 | F13: =AVERAGE('월별 매출'!D32:F32) -> 9.7220503e+08 | G13: =AVERAGE('월별 매출'!J32:L32) -> 1.0527717e+09 | H13: =IF(F13=0,"",G13/F13-1) -> 0.082870077 | I13: ='월별 매출'!L32 -> 923064584 | J13: ='월별 매출'!U32 -> -0.14995656 | K13: ='주별 매출'!BM32 -> 175392743 | L13: =IF('주별 매출'!BL32=0,"",K13/'주별 매출'!BL32-1) -> -0.12053544 | M13: =SUM('주별 매출'!BJ32:BM32) -> 809206366 | N13: =SUM('주별 매출'!BF32:BI32) -> 838879714 | O13: =IF(N13=0,"",M13/N13-1) -> -0.03537259 | P13: ='주별 매출'!M32 -> 188069686 | Q13: =IF(P13=0,"",K13/P13-1) -> -0.067405563 | R13: =IF($M$8=0,"",M13/$M$8) -> 0.040537382 | S13: =IF(AND(M13=0,N13=0),"-",IF(N13=0,"● 신규 발생",IF(M13=0,"■ 매출 중단",IF(O13>=0.05,"▲ 상승",IF(O13<=-0.05,"▼ 하락","― 보합"))))) -> ― 보합 | T13: =IF(AND(F13=0,G13=0),"-",IF(F13=0,"● 신규 발생",IF(G13=0,"■ 매출 중단",IF(H13>=0.05,"▲ 상승",IF(H13<=-0.05,"▼ 하락","― 보합"))))) -> ▲ 상승
A14: 6 | B14: 신규 | C14: B6135 | D14: 후참잘 대분류 | E14: ='주별 매출'!D24 -> 65 | F14: =AVERAGE('월별 매출'!D24:F24) -> 0 | G14: =AVERAGE('월별 매출'!J24:L24) -> 43442000 | H14: =IF(F14=0,"",G14/F14-1) | I14: ='월별 매출'!L24 -> 43500000 | J14: ='월별 매출'!U24 -> 0.0017040483 | K14: ='주별 매출'!BM24 -> 199827991 | L14: =IF('주별 매출'!BL24=0,"",K14/'주별 매출'!BL24-1) -> 0.15272184 | M14: =SUM('주별 매출'!BJ24:BM24) -> 753313179 | N14: =SUM('주별 매출'!BF24:BI24) -> 682285288 | O14: =IF(N14=0,"",M14/N14-1) -> 0.10410292 | P14: ='주별 매출'!M24 -> 0 | Q14: =IF(P14=0,"",K14/P14-1) | R14: =IF($M$8=0,"",M14/$M$8) -> 0.0377374 | S14: =IF(AND(M14=0,N14=0),"-",IF(N14=0,"● 신규 발생",IF(M14=0,"■ 매출 중단",IF(O14>=0.05,"▲ 상승",IF(O14<=-0.05,"▼ 하락","― 보합"))))) -> ▲ 상승 | T14: =IF(AND(F14=0,G14=0),"-",IF(F14=0,"● 신규 발생",IF(G14=0,"■ 매출 중단",IF(H14>=0.05,"▲ 상승",IF(H14<=-0.05,"▼ 하락","― 보합"))))) -> ● 신규 발생 | U14: 월간 시트는 3PL 코드(S258544, 후참잘 대분류(3pl))만 집계되어 주간 대비 월 매출이 과소 계상됨
A15: 7 | B15: 기존 | C15: S95143 | D15: FR_미스앤미스터 | E15: ='주별 매출'!D97 -> 150 | F15: =AVERAGE('월별 매출'!D97:F97) -> 8.0304932e+08 | G15: =AVERAGE('월별 매출'!J97:L97) -> 620241541 | H15: =IF(F15=0,"",G15/F15-1) -> -0.22764203 | I15: ='월별 매출'!L97 -> 648818993 | J15: ='월별 매출'!U97 -> 0.096185311 | K15: ='주별 매출'!BM97 -> 164270230 | L15: =IF('주별 매출'!BL97=0,"",K15/'주별 매출'!BL97-1) -> -0.017884809 | M15: =SUM('주별 매출'!BJ97:BM97) -> 646136281 | N15: =SUM('주별 매출'!BF97:BI97) -> 586375069 | O15: =IF(N15=0,"",M15/N15-1) -> 0.10191636 | P15: ='주별 매출'!M97 -> 209047596 | Q15: =IF(P15=0,"",K15/P15-1) -> -0.21419699 | R15: =IF($M$8=0,"",M15/$M$8) -> 0.032368348 | S15: =IF(AND(M15=0,N15=0),"-",IF(N15=0,"● 신규 발생",IF(M15=0,"■ 매출 중단",IF(O15>=0.05,"▲ 상승",IF(O15<=-0.05,"▼ 하락","― 보합"))))) -> ▲ 상승 | T15: =IF(AND(F15=0,G15=0),"-",IF(F15=0,"● 신규 발생",IF(G15=0,"■ 매출 중단",IF(H15>=0.05,"▲ 상승",IF(H15<=-0.05,"▼ 하락","― 보합"))))) -> ▼ 하락
A16: 8 | B16: 기존 | C16: S97169 | D16: 달떡볶이 대코드 | E16: ='주별 매출'!D100 -> 90 | F16: =AVERAGE('월별 매출'!D100:F100) -> 617402637 | G16: =AVERAGE('월별 매출'!J100:L100) -> 6.6912545e+08 | H16: =IF(F16=0,"",G16/F16-1) -> 0.083774857 | I16: ='월별 매출'!L100 -> 647505974 | J16: ='월별 매출'!U100 -> -0.039924969 | K16: ='주별 매출'!BM100 -> 159596324 | L16: =IF('주별 매출'!BL100=0,"",K16/'주별 매출'!BL100-1) -> -0.012265855 | M16: =SUM('주별 매출'!BJ100:BM100) -> 618991241 | N16: =SUM('주별 매출'!BF100:BI100) -> 611951290 | O16: =IF(N16=0,"",M16/N16-1) -> 0.011504104 | P16: ='주별 매출'!M100 -> 141221320 | Q16: =IF(P16=0,"",K16/P16-1) -> 0.13011494 | R16: =IF($M$8=0,"",M16/$M$8) -> 0.031008511 | S16: =IF(AND(M16=0,N16=0),"-",IF(N16=0,"● 신규 발생",IF(M16=0,"■ 매출 중단",IF(O16>=0.05,"▲ 상승",IF(O16<=-0.05,"▼ 하락","― 보합"))))) -> ― 보합 | T16: =IF(AND(F16=0,G16=0),"-",IF(F16=0,"● 신규 발생",IF(G16=0,"■ 매출 중단",IF(H16>=0.05,"▲ 상승",IF(H16<=-0.05,"▼ 하락","― 보합"))))) -> ▲ 상승
A17: 9 | B17: 기존 | C17: S236674 | D17: 치킨플러스 대분류 | E17: ='주별 매출'!D56 -> 121 | F17: =AVERAGE('월별 매출'!D56:F56) -> 7.8657774e+08 | G17: =AVERAGE('월별 매출'!J56:L56) -> 7.5335595e+08 | H17: =IF(F17=0,"",G17/F17-1) -> -0.042235856 | I17: ='월별 매출'!L56 -> 647185061 | J17: ='월별 매출'!U56 -> -0.1784791 | K17: ='주별 매출'!BM56 -> 125441955 | L17: =IF('주별 매출'!BL56=0,"",K17/'주별 매출'!BL56-1) -> -0.080898333 | M17: =SUM('주별 매출'!BJ56:BM56) -> 535553088 | N17: =SUM('주별 매출'!BF56:BI56) -> 614293428 | O17: =IF(N17=0,"",M17/N17-1) -> -0.12818034 | P17: ='주별 매출'!M56 -> 0 | Q17: =IF(P17=0,"",K17/P17-1) | R17: =IF($M$8=0,"",M17/$M$8) -> 0.026828657 | S17: =IF(AND(M17=0,N17=0),"-",IF(N17=0,"● 신규 발생",IF(M17=0,"■ 매출 중단",IF(O17>=0.05,"▲ 상승",IF(O17<=-0.05,"▼ 하락","― 보합"))))) -> ▼ 하락 | T17: =IF(AND(F17=0,G17=0),"-",IF(F17=0,"● 신규 발생",IF(G17=0,"■ 매출 중단",IF(H17>=0.05,"▲ 상승",IF(H17<=-0.05,"▼ 하락","― 보합"))))) -> ― 보합
A18: 10 | B18: 기존 | C18: S234496 | D18: 킹콩 대코드 | E18: ='주별 매출'!D54 -> 98 | F18: =AVERAGE('월별 매출'!D54:F54) -> 6.0879977e+08 | G18: =AVERAGE('월별 매출'!J54:L54) -> 5.3997587e+08 | H18: =IF(F18=0,"",G18/F18-1) -> -0.11304849 | I18: ='월별 매출'!L54 -> 537800968 | J18: ='월별 매출'!U54 -> 0.0080390765 | K18: ='주별 매출'!BM54 -> 130932050 | L18: =IF('주별 매출'!BL54=0,"",K18/'주별 매출'!BL54-1) -> 0.023052737 | M18: =SUM('주별 매출'!BJ54:BM54) -> 491718808 | N18: =SUM('주별 매출'!BF54:BI54) -> 511015645 | O18: =IF(N18=0,"",M18/N18-1) -> -0.037761734 | P18: ='주별 매출'!M54 -> 0 | Q18: =IF(P18=0,"",K18/P18-1) | R18: =IF($M$8=0,"",M18/$M$8) -> 0.024632769 | S18: =IF(AND(M18=0,N18=0),"-",IF(N18=0,"● 신규 발생",IF(M18=0,"■ 매출 중단",IF(O18>=0.05,"▲ 상승",IF(O18<=-0.05,"▼ 하락","― 보합"))))) -> ― 보합 | T18: =IF(AND(F18=0,G18=0),"-",IF(F18=0,"● 신규 발생",IF(G18=0,"■ 매출 중단",IF(H18>=0.05,"▲ 상승",IF(H18<=-0.05,"▼ 하락","― 보합"))))) -> ▼ 하락
A19: 11 | B19: 기존 | C19: S206764 | D19: (유)가로수브랜딩_숯토리(대) | E19: ='주별 매출'!D70 -> 65 | F19: =AVERAGE('월별 매출'!D70:F70) -> 2.9532889e+08 | G19: =AVERAGE('월별 매출'!J70:L70) -> 483288698 | H19: =IF(F19=0,"",G19/F19-1) -> 0.63644232 | I19: ='월별 매출'!L70 -> 509432352 | J19: ='월별 매출'!U70 -> 0.066908304 | K19: ='주별 매출'!BM70 -> 108601911 | L19: =IF('주별 매출'!BL70=0,"",K19/'주별 매출'!BL70-1) -> -0.08214405 | M19: =SUM('주별 매출'!BJ70:BM70) -> 479753758 | N19: =SUM('주별 매출'!BF70:BI70) -> 445737992 | O19: =IF(N19=0,"",M19/N19-1) -> 0.076313365 | P19: ='주별 매출'!M70 -> 49398660 | Q19: =IF(P19=0,"",K19/P19-1) -> 1.1984789 | R19: =IF($M$8=0,"",M19/$M$8) -> 0.024033377 | S19: =IF(AND(M19=0,N19=0),"-",IF(N19=0,"● 신규 발생",IF(M19=0,"■ 매출 중단",IF(O19>=0.05,"▲ 상승",IF(O19<=-0.05,"▼ 하락","― 보합"))))) -> ▲ 상승 | T19: =IF(AND(F19=0,G19=0),"-",IF(F19=0,"● 신규 발생",IF(G19=0,"■ 매출 중단",IF(H19>=0.05,"▲ 상승",IF(H19<=-0.05,"▼ 하락","― 보합"))))) -> ▲ 상승
A20: 12 | B20: 기존 | C20: S101744 | D20: 화락바베큐 대 (HFBG 주식회사) | E20: ='주별 매출'!D61 -> 156 | F20: =AVERAGE('월별 매출'!D61:F61) -> 466913743 | G20: =AVERAGE('월별 매출'!J61:L61) -> 4.7995895e+08 | H20: =IF(F20=0,"",G20/F20-1) -> 0.027939213 | I20: ='월별 매출'!L61 -> 471967420 | J20: ='월별 매출'!U61 -> 0.016231627 | K20: ='주별 매출'!BM61 -> 105584297 | L20: =IF('주별 매출'!BL61=0,"",K20/'주별 매출'!BL61-1) -> 0.073701973 | M20: =SUM('주별 매출'!BJ61:BM61) -> 418475423 | N20: =SUM('주별 매출'!BF61:BI61) -> 428508845 | O20: =IF(N20=0,"",M20/N20-1) -> -0.023414737 | P20: ='주별 매출'!M61 -> 207243968 | Q20: =IF(P20=0,"",K20/P20-1) -> -0.49053139 | R20: =IF($M$8=0,"",M20/$M$8) -> 0.020963624 | S20: =IF(AND(M20=0,N20=0),"-",IF(N20=0,"● 신규 발생",IF(M20=0,"■ 매출 중단",IF(O20>=0.05,"▲ 상승",IF(O20<=-0.05,"▼ 하락","― 보합"))))) -> ― 보합 | T20: =IF(AND(F20=0,G20=0),"-",IF(F20=0,"● 신규 발생",IF(G20=0,"■ 매출 중단",IF(H20>=0.05,"▲ 상승",IF(H20<=-0.05,"▼ 하락","― 보합"))))) -> ― 보합
A21: 13 | B21: 기존 | C21: S94835 | D21: 메이크어딜리버리 대분류 | E21: ='주별 매출'!D95 -> 36 | F21: =AVERAGE('월별 매출'!D95:F95) -> 5.4393103e+08 | G21: =AVERAGE('월별 매출'!J95:L95) -> 4.800746e+08 | H21: =IF(F21=0,"",G21/F21-1) -> -0.11739802 | I21: ='월별 매출'!L95 -> 418767227 | J21: ='월별 매출'!U95 -> -0.17493845 | K21: ='주별 매출'!BM95 -> 104431901 | L21: =IF('주별 매출'!BL95=0,"",K21/'주별 매출'!BL95-1) -> 0.077616475 | M21: =SUM('주별 매출'!BJ95:BM95) -> 387374987 | N21: =SUM('주별 매출'!BF95:BI95) -> 410359916 | O21: =IF(N21=0,"",M21/N21-1) -> -0.056011633 | P21: ='주별 매출'!M95 -> 145666160 | Q21: =IF(P21=0,"",K21/P21-1) -> -0.2830737 | R21: =IF($M$8=0,"",M21/$M$8) -> 0.019405641 | S21: =IF(AND(M21=0,N21=0),"-",IF(N21=0,"● 신규 발생",IF(M21=0,"■ 매출 중단",IF(O21>=0.05,"▲ 상승",IF(O21<=-0.05,"▼ 하락","― 보합"))))) -> ▼ 하락 | T21: =IF(AND(F21=0,G21=0),"-",IF(F21=0,"● 신규 발생",IF(G21=0,"■ 매출 중단",IF(H21>=0.05,"▲ 상승",IF(H21<=-0.05,"▼ 하락","― 보합"))))) -> ▼ 하락
A22: 14 | B22: 기존 | C22: S226276 | D22: 구도로통닭(대) | E22: ='주별 매출'!D43 -> 44 | F22: =AVERAGE('월별 매출'!D43:F43) -> 3.4065639e+08 | G22: =AVERAGE('월별 매출'!J43:L43) -> 387494188 | H22: =IF(F22=0,"",G22/F22-1) -> 0.1374928 | I22: ='월별 매출'!L43 -> 357564124 | J22: ='월별 매출'!U43 -> -0.11140972 | K22: ='주별 매출'!BM43 -> 78571576 | L22: =IF('주별 매출'!BL43=0,"",K22/'주별 매출'!BL43-1) -> -0.11057793 | M22: =SUM('주별 매출'!BJ43:BM43) -> 337270983 | N22: =SUM('주별 매출'!BF43:BI43) -> 336070619 | O22: =IF(N22=0,"",M22/N22-1) -> 0.0035717612 | P22: ='주별 매출'!M43 -> 85421905 | Q22: =IF(P22=0,"",K22/P22-1) -> -0.080194056 | R22: =IF($M$8=0,"",M22/$M$8) -> 0.016895669 | S22: =IF(AND(M22=0,N22=0),"-",IF(N22=0,"● 신규 발생",IF(M22=0,"■ 매출 중단",IF(O22>=0.05,"▲ 상승",IF(O22<=-0.05,"▼ 하락","― 보합"))))) -> ― 보합 | T22: =IF(AND(F22=0,G22=0),"-",IF(F22=0,"● 신규 발생",IF(G22=0,"■ 매출 중단",IF(H22>=0.05,"▲ 상승",IF(H22<=-0.05,"▼ 하락","― 보합"))))) -> ▲ 상승
A23: 15 | B23: 기존 | C23: S90344 | D23: 화화돼지왕갈비 (대) | E23: ='주별 매출'!D89 -> 49 | F23: =AVERAGE('월별 매출'!D89:F89) -> 344227728 | G23: =AVERAGE('월별 매출'!J89:L89) -> 3.5017146e+08 | H23: =IF(F23=0,"",G23/F23-1) -> 0.017266852 | I23: ='월별 매출'!L89 -> 321555443 | J23: ='월별 매출'!U89 -> -0.15332758 | K23: ='주별 매출'!BM89 -> 75092601 | L23: =IF('주별 매출'!BL89=0,"",K23/'주별 매출'!BL89-1) -> -0.038805849 | M23: =SUM('주별 매출'!BJ89:BM89) -> 313156052 | N23: =SUM('주별 매출'!BF89:BI89) -> 307356596 | O23: =IF(N23=0,"",M23/N23-1) -> 0.018868819 | P23: ='주별 매출'!M89 -> 64550555 | Q23: =IF(P23=0,"",K23/P23-1) -> 0.16331457 | R23: =IF($M$8=0,"",M23/$M$8) -> 0.015687626 | S23: =IF(AND(M23=0,N23=0),"-",IF(N23=0,"● 신규 발생",IF(M23=0,"■ 매출 중단",IF(O23>=0.05,"▲ 상승",IF(O23<=-0.05,"▼ 하락","― 보합"))))) -> ― 보합 | T23: =IF(AND(F23=0,G23=0),"-",IF(F23=0,"● 신규 발생",IF(G23=0,"■ 매출 중단",IF(H23>=0.05,"▲ 상승",IF(H23<=-0.05,"▼ 하락","― 보합"))))) -> ― 보합
A24: 16 | B24: 기존 | C24: S94092 | D24: 마루에프씨 대코드 | E24: ='주별 매출'!D93 -> 39 | F24: =AVERAGE('월별 매출'!D93:F93) -> 293087894 | G24: =AVERAGE('월별 매출'!J93:L93) -> 3.4548166e+08 | H24: =IF(F24=0,"",G24/F24-1) -> 0.1787647 | I24: ='월별 매출'!L93 -> 356018386 | J24: ='월별 매출'!U93 -> 0.028179872 | K24: ='주별 매출'!BM93 -> 76920879 | L24: =IF('주별 매출'!BL93=0,"",K24/'주별 매출'!BL93-1) -> 0.0099536809 | M24: =SUM('주별 매출'!BJ93:BM93) -> 279340598 | N24: =SUM('주별 매출'!BF93:BI93) -> 316505279 | O24: =IF(N24=0,"",M24/N24-1) -> -0.11742199 | P24: ='주별 매출'!M93 -> 57309608 | Q24: =IF(P24=0,"",K24/P24-1) -> 0.34219866 | R24: =IF($M$8=0,"",M24/$M$8) -> 0.013993633 | S24: =IF(AND(M24=0,N24=0),"-",IF(N24=0,"● 신규 발생",IF(M24=0,"■ 매출 중단",IF(O24>=0.05,"▲ 상승",IF(O24<=-0.05,"▼ 하락","― 보합"))))) -> ▼ 하락 | T24: =IF(AND(F24=0,G24=0),"-",IF(F24=0,"● 신규 발생",IF(G24=0,"■ 매출 중단",IF(H24>=0.05,"▲ 상승",IF(H24<=-0.05,"▼ 하락","― 보합"))))) -> ▲ 상승
A25: 17 | B25: 기존 | C25: S227002 / S254367 | D25: 돈카춘 대코드 | E25: ='주별 매출'!D44 -> 42 | F25: =AVERAGE('월별 매출'!D44:F44) -> 270830086 | G25: =AVERAGE('월별 매출'!J44:L44) -> 299897891 | H25: =IF(F25=0,"",G25/F25-1) -> 0.10732857 | I25: ='월별 매출'!L44 -> 287180887 | J25: ='월별 매출'!U44 -> -0.042887927 | K25: ='주별 매출'!BM44 -> 66783714 | L25: =IF('주별 매출'!BL44=0,"",K25/'주별 매출'!BL44-1) -> -0.028437965 | M25: =SUM('주별 매출'!BJ44:BM44) -> 261652229 | N25: =SUM('주별 매출'!BF44:BI44) -> 277174493 | O25: =IF(N25=0,"",M25/N25-1) -> -0.056001776 | P25: ='주별 매출'!M44 -> 61888510 | Q25: =IF(P25=0,"",K25/P25-1) -> 0.079097138 | R25: =IF($M$8=0,"",M25/$M$8) -> 0.01310753 | S25: =IF(AND(M25=0,N25=0),"-",IF(N25=0,"● 신규 발생",IF(M25=0,"■ 매출 중단",IF(O25>=0.05,"▲ 상승",IF(O25<=-0.05,"▼ 하락","― 보합"))))) -> ▼ 하락 | T25: =IF(AND(F25=0,G25=0),"-",IF(F25=0,"● 신규 발생",IF(G25=0,"■ 매출 중단",IF(H25>=0.05,"▲ 상승",IF(H25<=-0.05,"▼ 하락","― 보합"))))) -> ▲ 상승 | U25: 본점코드 변경으로 원본에 2행으로 나뉘어 있어 합산
A26: 18 | B26: 기존 | C26: S220382 | D26: 주식회사 인생푸드 | E26: ='주별 매출'!D33 -> 193 | F26: =AVERAGE('월별 매출'!D33:F33) -> 322441952 | G26: =AVERAGE('월별 매출'!J33:L33) -> 3.1129066e+08 | H26: =IF(F26=0,"",G26/F26-1) -> -0.034583861 | I26: ='월별 매출'!L33 -> 297556403 | J26: ='월별 매출'!U33 -> -0.096043336 | K26: ='주별 매출'!BM33 -> 57014380 | L26: =IF('주별 매출'!BL33=0,"",K26/'주별 매출'!BL33-1) -> -0.042675799 | M26: =SUM('주별 매출'!BJ33:BM33) -> 255379419 | N26: =SUM('주별 매출'!BF33:BI33) -> 276840922 | O26: =IF(N26=0,"",M26/N26-1) -> -0.077522871 | P26: ='주별 매출'!M33 -> 53048916 | Q26: =IF(P26=0,"",K26/P26-1) -> 0.074751084 | R26: =IF($M$8=0,"",M26/$M$8) -> 0.012793292 | S26: =IF(AND(M26=0,N26=0),"-",IF(N26=0,"● 신규 발생",IF(M26=0,"■ 매출 중단",IF(O26>=0.05,"▲ 상승",IF(O26<=-0.05,"▼ 하락","― 보합"))))) -> ▼ 하락 | T26: =IF(AND(F26=0,G26=0),"-",IF(F26=0,"● 신규 발생",IF(G26=0,"■ 매출 중단",IF(H26>=0.05,"▲ 상승",IF(H26<=-0.05,"▼ 하락","― 보합"))))) -> ― 보합
A27: 19 | B27: 기존 | C27: S72152 | D27: 쥬씨_쥬씨 주식회사_대분류 | E27: ='주별 매출'!D77 -> 120 | F27: =AVERAGE('월별 매출'!D77:F77) -> 2.3195049e+08 | G27: =AVERAGE('월별 매출'!J77:L77) -> 302340777 | H27: =IF(F27=0,"",G27/F27-1) -> 0.30347119 | I27: ='월별 매출'!L77 -> 262513875 | J27: ='월별 매출'!U77 -> -0.18243562 | K27: ='주별 매출'!BM77 -> 55469374 | L27: =IF('주별 매출'!BL77=0,"",K27/'주별 매출'!BL77-1) -> -0.039029062 | M27: =SUM('주별 매출'!BJ77:BM77) -> 229617350 | N27: =SUM('주별 매출'!BF77:BI77) -> 254514119 | O27: =IF(N27=0,"",M27/N27-1) -> -0.097820777 | P27: ='주별 매출'!M77 -> 60256370 | Q27: =IF(P27=0,"",K27/P27-1) -> -0.079443816 | R27: =IF($M$8=0,"",M27/$M$8) -> 0.011502735 | S27: =IF(AND(M27=0,N27=0),"-",IF(N27=0,"● 신규 발생",IF(M27=0,"■ 매출 중단",IF(O27>=0.05,"▲ 상승",IF(O27<=-0.05,"▼ 하락","― 보합"))))) -> ▼ 하락 | T27: =IF(AND(F27=0,G27=0),"-",IF(F27=0,"● 신규 발생",IF(G27=0,"■ 매출 중단",IF(H27>=0.05,"▲ 상승",IF(H27<=-0.05,"▼ 하락","― 보합"))))) -> ▲ 상승
A28: 20 | B28: 기존 | C28: S87905 | D28: 미아리우동집 (대) | E28: ='주별 매출'!D84 -> 34 | F28: =AVERAGE('월별 매출'!D84:F84) -> 250125118 | G28: =AVERAGE('월별 매출'!J84:L84) -> 235268366 | H28: =IF(F28=0,"",G28/F28-1) -> -0.059397281 | I28: ='월별 매출'!L84 -> 221498108 | J28: ='월별 매출'!U84 -> -0.10093835 | K28: ='주별 매출'!BM84 -> 56388188 | L28: =IF('주별 매출'!BL84=0,"",K28/'주별 매출'!BL84-1) -> 0.056445155 | M28: =SUM('주별 매출'!BJ84:BM84) -> 205541434 | N28: =SUM('주별 매출'!BF84:BI84) -> 214292316 | O28: =IF(N28=0,"",M28/N28-1) -> -0.040836191 | P28: ='주별 매출'!M84 -> 50180770 | Q28: =IF(P28=0,"",K28/P28-1) -> 0.12370113 | R28: =IF($M$8=0,"",M28/$M$8) -> 0.010296646 | S28: =IF(AND(M28=0,N28=0),"-",IF(N28=0,"● 신규 발생",IF(M28=0,"■ 매출 중단",IF(O28>=0.05,"▲ 상승",IF(O28<=-0.05,"▼ 하락","― 보합"))))) -> ― 보합 | T28: =IF(AND(F28=0,G28=0),"-",IF(F28=0,"● 신규 발생",IF(G28=0,"■ 매출 중단",IF(H28>=0.05,"▲ 상승",IF(H28<=-0.05,"▼ 하락","― 보합"))))) -> ▼ 하락
A29: 21 | B29: 기존 | C29: S96803 | D29: 손큰할매순대국(대)(법인) | E29: ='주별 매출'!D98 -> 43 | F29: =AVERAGE('월별 매출'!D98:F98) -> 2.051925e+08 | G29: =AVERAGE('월별 매출'!J98:L98) -> 2.0032799e+08 | H29: =IF(F29=0,"",G29/F29-1) -> -0.023707051 | I29: ='월별 매출'!L98 -> 219647396 | J29: ='월별 매출'!U98 -> 0.12296599 | K29: ='주별 매출'!BM98 -> 51855753 | L29: =IF('주별 매출'!BL98=0,"",K29/'주별 매출'!BL98-1) -> 0.11841581 | M29: =SUM('주별 매출'!BJ98:BM98) -> 192881064 | N29: =SUM('주별 매출'!BF98:BI98) -> 204584713 | O29: =IF(N29=0,"",M29/N29-1) -> -0.05720686 | P29: ='주별 매출'!M98 -> 44872386 | Q29: =IF(P29=0,"",K29/P29-1) -> 0.15562727 | R29: =IF($M$8=0,"",M29/$M$8) -> 0.0096624221 | S29: =IF(AND(M29=0,N29=0),"-",IF(N29=0,"● 신규 발생",IF(M29=0,"■ 매출 중단",IF(O29>=0.05,"▲ 상승",IF(O29<=-0.05,"▼ 하락","― 보합"))))) -> ▼ 하락 | T29: =IF(AND(F29=0,G29=0),"-",IF(F29=0,"● 신규 발생",IF(G29=0,"■ 매출 중단",IF(H29>=0.05,"▲ 상승",IF(H29<=-0.05,"▼ 하락","― 보합"))))) -> ― 보합
A30: 22 | B30: 기존 | C30: S223642 | D30: 함께그린 대코드 | E30: ='주별 매출'!D37 -> 70 | F30: =AVERAGE('월별 매출'!D37:F37) -> 2.7180013e+08 | G30: =AVERAGE('월별 매출'!J37:L37) -> 225091886 | H30: =IF(F30=0,"",G30/F30-1) -> -0.17184775 | I30: ='월별 매출'!L37 -> 225175374 | J30: ='월별 매출'!U37 -> 0.043796826 | K30: ='주별 매출'!BM37 -> 39354545 | L30: =IF('주별 매출'!BL37=0,"",K30/'주별 매출'!BL37-1) -> -0.14585551 | M30: =SUM('주별 매출'!BJ37:BM37) -> 189562578 | N30: =SUM('주별 매출'!BF37:BI37) -> 200912386 | O30: =IF(N30=0,"",M30/N30-1) -> -0.056491331 | P30: ='주별 매출'!M37 -> 70260734 | Q30: =IF(P30=0,"",K30/P30-1) -> -0.43987854 | R30: =IF($M$8=0,"",M30/$M$8) -> 0.0094961818 | S30: =IF(AND(M30=0,N30=0),"-",IF(N30=0,"● 신규 발생",IF(M30=0,"■ 매출 중단",IF(O30>=0.05,"▲ 상승",IF(O30<=-0.05,"▼ 하락","― 보합"))))) -> ▼ 하락 | T30: =IF(AND(F30=0,G30=0),"-",IF(F30=0,"● 신규 발생",IF(G30=0,"■ 매출 중단",IF(H30>=0.05,"▲ 상승",IF(H30<=-0.05,"▼ 하락","― 보합"))))) -> ▼ 하락
A31: 23 | B31: 신규 | C31: S265753 | D31: 버거앤타코 | E31: ='주별 매출'!D27 -> 48 | F31: =AVERAGE('월별 매출'!D27:F27) -> 0 | G31: =AVERAGE('월별 매출'!J27:L27) -> 29506198 | H31: =IF(F31=0,"",G31/F31-1) | I31: ='월별 매출'!L27 -> 88518594 | J31: ='월별 매출'!U27 | K31: ='주별 매출'!BM27 -> 51039770 | L31: =IF('주별 매출'!BL27=0,"",K31/'주별 매출'!BL27-1) -> 0.061846381 | M31: =SUM('주별 매출'!BJ27:BM27) -> 181559154 | N31: =SUM('주별 매출'!BF27:BI27) -> 28781160 | O31: =IF(N31=0,"",M31/N31-1) -> 5.3082639 | P31: ='주별 매출'!M27 -> 0 | Q31: =IF(P31=0,"",K31/P31-1) | R31: =IF($M$8=0,"",M31/$M$8) -> 0.0090952484 | S31: =IF(AND(M31=0,N31=0),"-",IF(N31=0,"● 신규 발생",IF(M31=0,"■ 매출 중단",IF(O31>=0.05,"▲ 상승",IF(O31<=-0.05,"▼ 하락","― 보합"))))) -> ▲ 상승 | T31: =IF(AND(F31=0,G31=0),"-",IF(F31=0,"● 신규 발생",IF(G31=0,"■ 매출 중단",IF(H31>=0.05,"▲ 상승",IF(H31<=-0.05,"▼ 하락","― 보합"))))) -> ● 신규 발생
A32: 24 | B32: 신규 | C32: S251614 | D32: 고기궁전 대분류 | E32: ='주별 매출'!D21 -> 26 | F32: =AVERAGE('월별 매출'!D21:F21) -> 0 | G32: =AVERAGE('월별 매출'!J21:L21) -> 2.0558557e+08 | H32: =IF(F32=0,"",G32/F32-1) | I32: ='월별 매출'!L21 -> 191663380 | J32: ='월별 매출'!U21 -> -0.057784665 | K32: ='주별 매출'!BM21 -> 41112660 | L32: =IF('주별 매출'!BL21=0,"",K32/'주별 매출'!BL21-1) -> -0.080601911 | M32: =SUM('주별 매출'!BJ21:BM21) -> 162145810 | N32: =SUM('주별 매출'!BF21:BI21) -> 188554820 | O32: =IF(N32=0,"",M32/N32-1) -> -0.14006012 | P32: ='주별 매출'!M21 -> 0 | Q32: =IF(P32=0,"",K32/P32-1) | R32: =IF($M$8=0,"",M32/$M$8) -> 0.0081227323 | S32: =IF(AND(M32=0,N32=0),"-",IF(N32=0,"● 신규 발생",IF(M32=0,"■ 매출 중단",IF(O32>=0.05,"▲ 상승",IF(O32<=-0.05,"▼ 하락","― 보합"))))) -> ▼ 하락 | T32: =IF(AND(F32=0,G32=0),"-",IF(F32=0,"● 신규 발생",IF(G32=0,"■ 매출 중단",IF(H32>=0.05,"▲ 상승",IF(H32<=-0.05,"▼ 하락","― 보합"))))) -> ● 신규 발생
A33: 25 | B33: 기존 | C33: S77411 | D33: 차얌,88핫도그_주식회사 프로젝트비_대분류 | E33: ='주별 매출'!D78 -> 44 | F33: =AVERAGE('월별 매출'!D78:F78) -> 1.107681e+08 | G33: =AVERAGE('월별 매출'!J78:L78) -> 1.9495219e+08 | H33: =IF(F33=0,"",G33/F33-1) -> 0.76000305 | I33: ='월별 매출'!L78 -> 178729832 | J33: ='월별 매출'!U78 -> -0.10606761 | K33: ='주별 매출'!BM78 -> 37274967 | L33: =IF('주별 매출'!BL78=0,"",K33/'주별 매출'!BL78-1) -> -0.048675836 | M33: =SUM('주별 매출'!BJ78:BM78) -> 150160541 | N33: =SUM('주별 매출'!BF78:BI78) -> 168168993 | O33: =IF(N33=0,"",M33/N33-1) -> -0.10708545 | P33: ='주별 매출'!M78 -> 43721845 | Q33: =IF(P33=0,"",K33/P33-1) -> -0.1474521 | R33: =IF($M$8=0,"",M33/$M$8) -> 0.0075223275 | S33: =IF(AND(M33=0,N33=0),"-",IF(N33=0,"● 신규 발생",IF(M33=0,"■ 매출 중단",IF(O33>=0.05,"▲ 상승",IF(O33<=-0.05,"▼ 하락","― 보합"))))) -> ▼ 하락 | T33: =IF(AND(F33=0,G33=0),"-",IF(F33=0,"● 신규 발생",IF(G33=0,"■ 매출 중단",IF(H33>=0.05,"▲ 상승",IF(H33<=-0.05,"▼ 하락","― 보합"))))) -> ▲ 상승
A34: 26 | B34: 기존 | C34: S86140 | D34: 오백국수 (대) | E34: ='주별 매출'!D82 -> 77 | F34: =AVERAGE('월별 매출'!D82:F82) -> 166236202 | G34: =AVERAGE('월별 매출'!J82:L82) -> 203149283 | H34: =IF(F34=0,"",G34/F34-1) -> 0.222052 | I34: ='월별 매출'!L82 -> 173425560 | J34: ='월별 매출'!U82 -> -0.20394874 | K34: ='주별 매출'!BM82 -> 44824180 | L34: =IF('주별 매출'!BL82=0,"",K34/'주별 매출'!BL82-1) -> 0.24109359 | M34: =SUM('주별 매출'!BJ82:BM82) -> 149785510 | N34: =SUM('주별 매출'!BF82:BI82) -> 180299900 | O34: =IF(N34=0,"",M34/N34-1) -> -0.16924241 | P34: ='주별 매출'!M82 -> 44990723 | Q34: =IF(P34=0,"",K34/P34-1) -> -0.0037017187 | R34: =IF($M$8=0,"",M34/$M$8) -> 0.0075035402 | S34: =IF(AND(M34=0,N34=0),"-",IF(N34=0,"● 신규 발생",IF(M34=0,"■ 매출 중단",IF(O34>=0.05,"▲ 상승",IF(O34<=-0.05,"▼ 하락","― 보합"))))) -> ▼ 하락 | T34: =IF(AND(F34=0,G34=0),"-",IF(F34=0,"● 신규 발생",IF(G34=0,"■ 매출 중단",IF(H34>=0.05,"▲ 상승",IF(H34<=-0.05,"▼ 하락","― 보합"))))) -> ▲ 상승
A35: 27 | B35: 기존 | C35: S227995 | D35: 쓰리비플러스(대) K비빔밥 | E35: ='주별 매출'!D46 -> 26 | F35: =AVERAGE('월별 매출'!D46:F46) -> 1.7185025e+08 | G35: =AVERAGE('월별 매출'!J46:L46) -> 1.4639859e+08 | H35: =IF(F35=0,"",G35/F35-1) -> -0.14810372 | I35: ='월별 매출'!L46 -> 128474090 | J35: ='월별 매출'!U46 -> -0.1598386 | K35: ='주별 매출'!BM46 -> 33840497 | L35: =IF('주별 매출'!BL46=0,"",K35/'주별 매출'!BL46-1) -> 0.10500701 | M35: =SUM('주별 매출'!BJ46:BM46) -> 118206607 | N35: =SUM('주별 매출'!BF46:BI46) -> 127513000 | O35: =IF(N35=0,"",M35/N35-1) -> -0.072983876 | P35: ='주별 매출'!M46 -> 30696540 | Q35: =IF(P35=0,"",K35/P35-1) -> 0.10242057 | R35: =IF($M$8=0,"",M35/$M$8) -> 0.0059215877 | S35: =IF(AND(M35=0,N35=0),"-",IF(N35=0,"● 신규 발생",IF(M35=0,"■ 매출 중단",IF(O35>=0.05,"▲ 상승",IF(O35<=-0.05,"▼ 하락","― 보합"))))) -> ▼ 하락 | T35: =IF(AND(F35=0,G35=0),"-",IF(F35=0,"● 신규 발생",IF(G35=0,"■ 매출 중단",IF(H35>=0.05,"▲ 상승",IF(H35<=-0.05,"▼ 하락","― 보합"))))) -> ▼ 하락
A36: 28 | B36: 신규 | C36: S251592 | D36: 감쪽 대분류 | E36: ='주별 매출'!D19 -> 13 | F36: =AVERAGE('월별 매출'!D19:F19) -> 0 | G36: =AVERAGE('월별 매출'!J19:L19) -> 1.3188904e+08 | H36: =IF(F36=0,"",G36/F36-1) | I36: ='월별 매출'!L19 -> 134170680 | J36: ='월별 매출'!U19 -> 0.0033358111 | K36: ='주별 매출'!BM19 -> 28083090 | L36: =IF('주별 매출'!BL19=0,"",K36/'주별 매출'!BL19-1) -> -0.0084396931 | M36: =SUM('주별 매출'!BJ19:BM19) -> 115466240 | N36: =SUM('주별 매출'!BF19:BI19) -> 125406480 | O36: =IF(N36=0,"",M36/N36-1) -> -0.079264166 | P36: ='주별 매출'!M19 -> 0 | Q36: =IF(P36=0,"",K36/P36-1) | R36: =IF($M$8=0,"",M36/$M$8) -> 0.0057843083 | S36: =IF(AND(M36=0,N36=0),"-",IF(N36=0,"● 신규 발생",IF(M36=0,"■ 매출 중단",IF(O36>=0.05,"▲ 상승",IF(O36<=-0.05,"▼ 하락","― 보합"))))) -> ▼ 하락 | T36: =IF(AND(F36=0,G36=0),"-",IF(F36=0,"● 신규 발생",IF(G36=0,"■ 매출 중단",IF(H36>=0.05,"▲ 상승",IF(H36<=-0.05,"▼ 하락","― 보합"))))) -> ● 신규 발생
A37: 29 | B37: 기존 | C37: S213979 | D37: 경성맥주_대분류 | E37: ='주별 매출'!D31 -> 44 | F37: =AVERAGE('월별 매출'!D31:F31) -> 102724925 | G37: =AVERAGE('월별 매출'!J31:L31) -> 148187264 | H37: =IF(F37=0,"",G37/F37-1) -> 0.44256386 | I37: ='월별 매출'!L31 -> 134444334 | J37: ='월별 매출'!U31 -> -0.11000045 | K37: ='주별 매출'!BM31 -> 23283396 | L37: =IF('주별 매출'!BL31=0,"",K37/'주별 매출'!BL31-1) -> -0.15826424 | M37: =SUM('주별 매출'!BJ31:BM31) -> 114330574 | N37: =SUM('주별 매출'!BF31:BI31) -> 123473433 | O37: =IF(N37=0,"",M37/N37-1) -> -0.074047176 | P37: ='주별 매출'!M31 -> 25437539 | Q37: =IF(P37=0,"",K37/P37-1) -> -0.084683624 | R37: =IF($M$8=0,"",M37/$M$8) -> 0.0057274169 | S37: =IF(AND(M37=0,N37=0),"-",IF(N37=0,"● 신규 발생",IF(M37=0,"■ 매출 중단",IF(O37>=0.05,"▲ 상승",IF(O37<=-0.05,"▼ 하락","― 보합"))))) -> ▼ 하락 | T37: =IF(AND(F37=0,G37=0),"-",IF(F37=0,"● 신규 발생",IF(G37=0,"■ 매출 중단",IF(H37>=0.05,"▲ 상승",IF(H37<=-0.05,"▼ 하락","― 보합"))))) -> ▲ 상승
A38: 30 | B38: 기존 | C38: S224496 | D38: 통불(대) | E38: ='주별 매출'!D39 -> 12 | F38: =AVERAGE('월별 매출'!D39:F39) -> 1.2070131e+08 | G38: =AVERAGE('월별 매출'!J39:L39) -> 1.2631879e+08 | H38: =IF(F38=0,"",G38/F38-1) -> 0.046540396 | I38: ='월별 매출'!L39 -> 121069235 | J38: ='월별 매출'!U39 -> -0.071725937 | K38: ='주별 매출'!BM39 -> 23780920 | L38: =IF('주별 매출'!BL39=0,"",K38/'주별 매출'!BL39-1) -> -0.052681876 | M38: =SUM('주별 매출'!BJ39:BM39) -> 105419580 | N38: =SUM('주별 매출'!BF39:BI39) -> 111309385 | O38: =IF(N38=0,"",M38/N38-1) -> -0.052913822 | P38: ='주별 매출'!M39 -> 27130180 | Q38: =IF(P38=0,"",K38/P38-1) -> -0.12345145 | R38: =IF($M$8=0,"",M38/$M$8) -> 0.0052810186 | S38: =IF(AND(M38=0,N38=0),"-",IF(N38=0,"● 신규 발생",IF(M38=0,"■ 매출 중단",IF(O38>=0.05,"▲ 상승",IF(O38<=-0.05,"▼ 하락","― 보합"))))) -> ▼ 하락 | T38: =IF(AND(F38=0,G38=0),"-",IF(F38=0,"● 신규 발생",IF(G38=0,"■ 매출 중단",IF(H38>=0.05,"▲ 상승",IF(H38<=-0.05,"▼ 하락","― 보합"))))) -> ― 보합
A39: 31 | B39: 기존 | C39: S92874 | D39: 와플샵(대) | E39: ='주별 매출'!D91 -> 20 | F39: =AVERAGE('월별 매출'!D91:F91) -> 88236397 | G39: =AVERAGE('월별 매출'!J91:L91) -> 93500709 | H39: =IF(F39=0,"",G39/F39-1) -> 0.059661457 | I39: ='월별 매출'!L91 -> 93063759 | J39: ='월별 매출'!U91 -> -0.0044033527 | K39: ='주별 매출'!BM91 -> 20265472 | L39: =IF('주별 매출'!BL91=0,"",K39/'주별 매출'!BL91-1) -> -0.1374013 | M39: =SUM('주별 매출'!BJ91:BM91) -> 84543047 | N39: =SUM('주별 매출'!BF91:BI91) -> 85592640 | O39: =IF(N39=0,"",M39/N39-1) -> -0.012262655 | P39: ='주별 매출'!M91 -> 18539282 | Q39: =IF(P39=0,"",K39/P39-1) -> 0.093109863 | R39: =IF($M$8=0,"",M39/$M$8) -> 0.0042352037 | S39: =IF(AND(M39=0,N39=0),"-",IF(N39=0,"● 신규 발생",IF(M39=0,"■ 매출 중단",IF(O39>=0.05,"▲ 상승",IF(O39<=-0.05,"▼ 하락","― 보합"))))) -> ― 보합 | T39: =IF(AND(F39=0,G39=0),"-",IF(F39=0,"● 신규 발생",IF(G39=0,"■ 매출 중단",IF(H39>=0.05,"▲ 상승",IF(H39<=-0.05,"▼ 하락","― 보합"))))) -> ▲ 상승
A40: 32 | B40: 기존 | C40: S97707 | D40: 순수덮밥(대) | E40: ='주별 매출'!D102 -> 45 | F40: =AVERAGE('월별 매출'!D102:F102) -> 1.0023493e+08 | G40: =AVERAGE('월별 매출'!J102:L102) -> 96495320 | H40: =IF(F40=0,"",G40/F40-1) -> -0.037308464 | I40: ='월별 매출'!L102 -> 96548640 | J40: ='월별 매출'!U102 -> 0.044052273 | K40: ='주별 매출'!BM102 -> 19537390 | L40: =IF('주별 매출'!BL102=0,"",K40/'주별 매출'!BL102-1) -> -0.094298697 | M40: =SUM('주별 매출'!BJ102:BM102) -> 77125320 | N40: =SUM('주별 매출'!BF102:BI102) -> 63865660 | O40: =IF(N40=0,"",M40/N40-1) -> 0.20761799 | P40: ='주별 매출'!M102 -> 27203150 | Q40: =IF(P40=0,"",K40/P40-1) -> -0.28179678 | R40: =IF($M$8=0,"",M40/$M$8) -> 0.003863611 | S40: =IF(AND(M40=0,N40=0),"-",IF(N40=0,"● 신규 발생",IF(M40=0,"■ 매출 중단",IF(O40>=0.05,"▲ 상승",IF(O40<=-0.05,"▼ 하락","― 보합"))))) -> ▲ 상승 | T40: =IF(AND(F40=0,G40=0),"-",IF(F40=0,"● 신규 발생",IF(G40=0,"■ 매출 중단",IF(H40>=0.05,"▲ 상승",IF(H40<=-0.05,"▼ 하락","― 보합"))))) -> ― 보합
A41: 33 | B41: 기존 | C41: S94912 | D41: 한라맥주 대 | E41: ='주별 매출'!D96 -> 25 | F41: =AVERAGE('월별 매출'!D96:F96) -> 96451261 | G41: =AVERAGE('월별 매출'!J96:L96) -> 86974541 | H41: =IF(F41=0,"",G41/F41-1) -> -0.098253981 | I41: ='월별 매출'!L96 -> 90894871 | J41: ='월별 매출'!U96 -> 0.11109885 | K41: ='주별 매출'!BM96 -> 12485315 | L41: =IF('주별 매출'!BL96=0,"",K41/'주별 매출'!BL96-1) -> -0.3475215 | M41: =SUM('주별 매출'!BJ96:BM96) -> 76438059 | N41: =SUM('주별 매출'!BF96:BI96) -> 78678322 | O41: =IF(N41=0,"",M41/N41-1) -> -0.028473701 | P41: ='주별 매출'!M96 -> 19199565 | Q41: =IF(P41=0,"",K41/P41-1) -> -0.34970844 | R41: =IF($M$8=0,"",M41/$M$8) -> 0.0038291825 | S41: =IF(AND(M41=0,N41=0),"-",IF(N41=0,"● 신규 발생",IF(M41=0,"■ 매출 중단",IF(O41>=0.05,"▲ 상승",IF(O41<=-0.05,"▼ 하락","― 보합"))))) -> ― 보합 | T41: =IF(AND(F41=0,G41=0),"-",IF(F41=0,"● 신규 발생",IF(G41=0,"■ 매출 중단",IF(H41>=0.05,"▲ 상승",IF(H41<=-0.05,"▼ 하락","― 보합"))))) -> ▼ 하락
...

Sheet 주별 매출
A1: 걸개처별 주간 매출 (원) — 출처: Weekly Brand Tracking 시트 [주 매출]
A3: 구분 | B3: 본점코드 | C3: 본점명 | D3: 매장수 (최근주) | E3: '25 8월 3주차 | F3: '25 8월 4주차 | G3: '25 9월 1주차 | H3: '25 9월 2주차 | I3: '25 9월 3주차 | J3: '25 9월 4주차 | K3: '25 10월 1주차 | L3: '25 10월 2주차 | M3: '25 10월 3주차 | N3: '25 10월 4주차 | O3: '25 10월 5주차 | P3: '25 11월 1주차 | Q3: '25 11월 2주차 | R3: '25 11월 3주차 | S3: '25 11월 4주차 | T3: '25 12월 1주차 | U3: '25 12월 2주차 | V3: '25 12월 3주차 | W3: '25 12월 4주차 | X3: '25 1월 1주차 | Y3: '26 1월 2주차 | Z3: '26 1월 3주차 | AA3: '26 1월 4주차 | AB3: '26 1월 5주차 | AC3: '26 2월 1주차 | AD3: '26 2월 2주차 | AE3: '26 2월 3주차 | AF3: '26 2월 4주차 | AG3: '26 3월 1주차 | AH3: '26 3월 2주차 | AI3: '26 3월 3주차 | AJ3: '26 3월 4주차 | AK3: '26 3월 5주차 | AL3: '26 4월 2주차 | AM3: '26 4월 3주차 | AN3: '26 4월 4주차 | AO3: '26 4월 5주차 | AP3: '26 5월 1주차 | AQ3: '26 5월 2주차 | AR3: '26 5월 3주차 | AS3: '26 5월 4주차 | AT3: '26 6월 1주차 | AU3: '26 6월 2주차 | AV3: '26 6월 3주차 | AW3: '26 6월 4주차 | AX3: '26 7월 1주차 | AY3: '26 7월 2주차 | AZ3: '26 7월 3주차 | BA3: '26 7월 4주차 | BB3: '26 7월 5주차 | BC3: '26 8월 1주차 | BD3: '26 8월 2주차 | BE3: '26 8월 3주차 | BF3: '26 8월 4주차 | BG3: '26 9월 1주차 | BH3: '26 9월 2주차 | BI3: '26 9월 3주차 | BJ3: '26 9월 4주차 | BK3: '26 10월 1주차 | BL3: '26 10월 2주차 | BM3: '26 10월 3주차
E4: 08/18~08/24 | F4: 08/25~08/31 | G4: 09/01~09/07 | H4: 09/08~09/14 | I4: 09/15~09/21 | J4: 09/22~09/28 | K4: 09/29~10/05 | L4: 10/06~10/12 | M4: 10/13~10/19 | N4: 10/20~10/26 | O4: 10/27~11/02 | P4: 11/03~11/09 | Q4: 11/10~11/16 | R4: 11/17~11/23 | S4: 11/24~11/30 | T4: 12/01~12/07 | U4: 12/08~12/14 | V4: 12/15~12/21 | W4: 12/22~12/28 | X4: 12/29~01/04 | Y4: 01/05~01/11 | Z4: 01/12~01/18 | AA4: 01/19~01/25 | AB4: 01/26~02/01 | AC4: 02/02~02/08 | AD4: 02/09~02/15 | AE4: 02/16~02/22 | AF4: 02/23~03/01 | AG4: 03/02~03/08 | AH4: 03/09~03/15 | AI4: 03/16~03/22 | AJ4: 03/23~03/29 | AK4: 03/30~04/05 | AL4: 04/06~04/12 | AM4: 04/13~04/19 | AN4: 04/20~04/26 | AO4: 04/27~05/03 | AP4: 05/04~05/10 | AQ4: 05/11~05/17 | AR4: 05/18~05/24 | AS4: 05/25~05/31 | AT4: 06/01~06/07 | AU4: 06/08~06/14 | AV4: 06/15~06/21 | AW4: 06/22~06/28 | AX4: 06/29~07/05 | AY4: 07/06~07/12 | AZ4: 07/13~07/19 | BA4: 07/20~07/26 | BB4: 07/27~08/02 | BC4: 08/03~08/09 | BD4: 08/10~08/16 | BE4: 08/17~08/23 | BF4: 08/24~08/30 | BG4: 08/31~09/06 | BH4: 09/07~09/13 | BI4: 09/14~09/20 | BJ4: 09/21~09/27 | BK4: 09/28~10/04 | BL4: 10/05~10/11 | BM4: 10/12~10/18
A5: 합계 | D5: =SUM(D6:D125) -> 3976 | E5: =SUM(E6:E125) -> 4135515239 | F5: =SUM(F6:F125) -> 4111175183 | G5: =SUM(G6:G125) -> 4616874818 | H5: =SUM(H6:H125) -> 4473570554 | I5: =SUM(I6:I125) -> 4407015120 | J5: =SUM(J6:J125) -> 4604880979 | K5: =SUM(K6:K125) -> 6937220576 | ... BM5: =SUM(BM6:BM125) -> 5010739067
A6: 신규 | B6: S240084 | C6: 찌개찝 대 | D6: 6 | E6: 0 | F6: 0 | G6: 0 | H6: 0 | I6: 0 | J6: 0 | K6: 0 | L6: 0 | M6: 0 | N6: 0 | O6: 0 | P6: 0 | Q6: 0 | R6: 0 | S6: 0 | T6: 0 | U6: 0 | V6: 0 | W6: 3877782 | X6: 6575320 | Y6: 4694590 | Z6: 7638080 | AA6: 7099840 | AB6: 5662332 | AC6: 7672610 | AD6: 9202580 | AE6: 5782940 | AF6: 5163450 | AG6: 7649990 | AH6: 6651890 | AI6: 6078630 | AJ6: 5798240 | AK6: 7192310 | AL6: 5452920 | AM6: 6255260 | AN6: 7040030 | AO6: 6884060 | AP6: 6524820 | AQ6: 6061820 | AR6: 5130270 | AS6: 6383840 | AT6: 5882860 | AU6: 6211770 | AV6: 5627190 | AW6: 5578490 | AX6: 6687460 | AY6: 4233150 | AZ6: 4161710 | BA6: 5693940 | BB6: 5148010 | BC6: 3665730 | BD6: 4441700 | BE6: 4202170 | BF6: 3877490 | BG6: 4173690 | BH6: 3860720 | BI6: 4615570 | BJ6: 5764530 | BK6: 2504930 | BL6: 2620230 | BM6: 4361210
A7: 신규 | B7: S243775 | C7: 비어프랜드 대 | D7: 21 | E7: 0 | F7: 0 | G7: 0 | H7: 0 | I7: 0 | J7: 0 | K7: 0 | L7: 0 | M7: 0 | N7: 0 | O7: 0 | P7: 0 | Q7: 0 | R7: 0 | S7: 0 | T7: 0 | U7: 0 | V7: 0 | W7: 0 | X7: 0 | Y7: 0 | Z7: 92690 | AA7: -92690 | AB7: 0 | AC7: 4911870 | AD7: 11775330 | AE7: 6137320 | AF7: 8413800 | AG7: 6120950 | AH7: 6845580 | AI7: 6475450 | AJ7: 7127930 | AK7: 5923690 | AL7: 7351670 | AM7: 7548150 | AN7: 7374740 | AO7: 7146430 | AP7: 8495780 | AQ7: 8664110 | AR7: 7707000 | AS7: 7446310 | AT7: 7052330 | AU7: 6572990 | AV7: 9393310 | AW7: 6746520 | AX7: 8435400 | AY7: 8117630 | AZ7: 7668190 | BA7: 6334320 | BB7: 5707870 | BC7: 7105610 | BD7: 5873750 | BE7: 6196170 | BF7: 5325030 | BG7: 4337740 | BH7: 5084450 | BI7: 6686140 | BJ7: 6657310 | BK7: 3855710 | BL7: 4478240 | BM7: 5586320
A8: 신규 | B8: S242492 | C8: 카페차이(대) | D8: 12 | E8: 0 | F8: 0 | G8: 0 | H8: 0 | I8: 0 | J8: 0 | K8: 0 | L8: 0 | M8: 0 | N8: 0 | O8: 0 | P8: 0 | Q8: 0 | R8: 0 | S8: 0 | T8: 0 | U8: 0 | V8: 0 | W8: 0 | X8: 0 | Y8: 0 | Z8: 0 | AA8: 0 | AB8: 1160912 | AC8: 2894171 | AD8: 4343275 | AE8: 1789417 | AF8: 4010993 | AG8: 2177923 | AH8: 2117185 | AI8: 3478550 | AJ8: 2460799 | AK8: 3463835 | AL8: 3950752 | AM8: 3930572 | AN8: 4402031 | AO8: 4612786 | AP8: 3041925 | AQ8: 2801449 | AR8: 3099416 | AS8: 2538538 | AT8: 3074723 | AU8: 2297039 | AV8: 2091267 | AW8: 2303806 | AX8: 2510779 | AY8: 2102795 | AZ8: 2189229 | BA8: 2268538 | BB8: 1251561 | BC8: 3118620 | BD8: 2221558 | BE8: 1723132 | BF8: 2496290 | BG8: 2584789 | BH8: 2090761 | BI8: 3061534 | BJ8: 1913323 | BK8: 2558509 | BL8: 1938768 | BM8: 2099112
A9: 신규 | B9: S244336 | C9: 순치킨 (대) | D9: 3 | E9: 0 | F9: 0 | G9: 0 | H9: 0 | I9: 0 | J9: 0 | K9: 0 | L9: 0 | M9: 0 | N9: 0 | O9: 0 | P9: 0 | Q9: 0 | R9: 0 | S9: 0 | T9: 0 | U9: 0 | V9: 0 | W9: 0 | X9: 0 | Y9: 0 | Z9: 0 | AA9: 0 | AB9: 0 | AC9: 11919504 | AD9: 19129733 | AE9: 6198470 | AF9: 13236858 | AG9: 10248825 | AH9: 11393199 | AI9: 10305749 | AJ9: 10553009 | AK9: 7741784 | AL9: 10171104 | AM9: 8821514 | AN9: 9595800 | AO9: 6797219 | AP9: 10409833 | AQ9: 6556885 | AR9: 8480265 | AS9: 6420200 | AT9: 7202520 | AU9: 4583750 | AV9: 4942580 | AW9: 4223745 | AX9: 3983320 | AY9: 3588190 | AZ9: 3888635 | BA9: 4333300 | BB9: 4586990 | BC9: 1924090 | BD9: 2706675 | BE9: 2743415 | BF9: 1322700 | BG9: 4514980 | BH9: 879385 | BI9: 1083280 | BJ9: 474945 | BK9: 1302575 | BL9: 723940 | BM9: 586398
A10: 신규 | B10: S245774 | C10: 찐심맥주 대 | D10: 0 | E10: 0 | F10: 0 | G10: 0 | H10: 0 | I10: 0 | J10: 0 | K10: 0 | L10: 0 | M10: 0 | N10: 0 | O10: 0 | P10: 0 | Q10: 0 | R10: 0 | S10: 0 | T10: 0 | U10: 0 | V10: 0 | W10: 0 | X10: 0 | Y10: 0 | Z10: 0 | AA10: 0 | AB10: 0 | AC10: 0 | AD10: 0 | AE10: 0 | AF10: 500040 | AG10: 487380 | AH10: 202640 | AI10: 539640 | AJ10: 717720 | AK10: 580790 | AL10: 414360 | AM10: 483540 | AN10: 644640 | AO10: 326560 | AP10: 194730 | AQ10: 0 | AR10: 0 | AS10: 0 | AT10: 0 | AU10: 0 | AV10: 0 | AW10: 0 | AX10: 0 | AY10: 0 | AZ10: 0 | BA10: 0 | BB10: 0 | BC10: 0 | BD10: 0 | BE10: 0 | BF10: 0 | BG10: 0 | BH10: 0 | BI10: 0 | BJ10: 0 | BK10: 0 | BL10: 0 | BM10: 0
A11: 신규 | B11: S90525 | C11: 준코 대분류 | D11: 136 | E11: 0 | F11: 0 | G11: 0 | H11: 0 | I11: 0 | J11: 0 | K11: 0 | L11: 0 | M11: 0 | N11: 0 | O11: 0 | P11: 0 | Q11: 0 | R11: 0 | S11: 0 | T11: 0 | U11: 0 | V11: 0 | W11: 0 | X11: 0 | Y11: 0 | Z11: 0 | AA11: 0 | AB11: 0 | AC11: 0 | AD11: 0 | AE11: 0 | AF11: 0 | AG11: 414991385 | AH11: 349912210 | AI11: 368949432 | AJ11: 353920730 | AK11: 373598572 | AL11: 355274613 | AM11: 377911983 | AN11: 357072638 | AO11: 422604677 | AP11: 411832895 | AQ11: 344212700 | AR11: 395269053 | AS11: 382414064 | AT11: 420584300 | AU11: 359432683 | AV11: 361200967 | AW11: 383471483 | AX11: 397907998 | AY11: 391270165 | AZ11: 420374674 | BA11: 380030577 | BB11: 384981842 | BC11: 413415835 | BD11: 434410369 | BE11: 401007557 | BF11: 388463347 | BG11: 413161362 | BH11: 387878468 | BI11: 430073352 | BJ11: 522305203 | BK11: 402709820 | BL11: 435295118 | BM11: 381044155
A12: 신규 | B12: S246240 | C12: 와이엔컴퍼니 대분류 | D12: 10 | E12: 0 | F12: 0 | G12: 0 | H12: 0 | I12: 0 | J12: 0 | K12: 0 | L12: 0 | M12: 0 | N12: 0 | O12: 0 | P12: 0 | Q12: 0 | R12: 0 | S12: 0 | T12: 0 | U12: 0 | V12: 0 | W12: 0 | X12: 0 | Y12: 0 | Z12: 0 | AA12: 0 | AB12: 0 | AC12: 0 | AD12: 0 | AE12: 0 | AF12: 0 | AG12: 4396406 | AH12: 4131795 | AI12: 2689724 | AJ12: 1831202 | AK12: 3260715 | AL12: 3283811 | AM12: 3192662 | AN12: 2499780 | AO12: 2468477 | AP12: 3115002 | AQ12: 1669033 | AR12: 6716779 | AS12: 5078456 | AT12: 2179613 | AU12: 3163195 | AV12: 2737039 | AW12: 1617690 | AX12: 3046366 | AY12: 2020873 | AZ12: 1964294 | BA12: 2985034 | BB12: 1396240 | BC12: 2719173 | BD12: 1869257 | BE12: 2233496 | BF12: 1828837 | BG12: 1813394 | BH12: 1514544 | BI12: 1133394 | BJ12: 1508565 | BK12: 1428738 | BL12: 1010432 | BM12: 2490888
A13: 신규 | B13: S247530 | C13: 포플로어 대분류 | D13: 8 | E13: 0 | F13: 0 | G13: 0 | H13: 0 | I13: 0 | J13: 0 | K13: 0 | L13: 0 | M13: 0 | N13: 0 | O13: 0 | P13: 0 | Q13: 0 | R13: 0 | S13: 0 | T13: 0 | U13: 0 | V13: 0 | W13: 0 | X13: 0 | Y13: 0 | Z13: 0 | AA13: 0 | AB13: 0 | AC13: 0 | AD13: 0 | AE13: 0 | AF13: 0 | AG13: 0 | AH13: 0 | AI13: 486250 | AJ13: 3373164 | AK13: 4411563 | AL13: 4965807 | AM13: 5401551 | AN13: 5967634 | AO13: 7654042 | AP13: 6487045 | AQ13: 6451229 | AR13: 8679208 | AS13: 6424670 | AT13: 8778838 | AU13: 8579744 | AV13: 8603977 | AW13: 7813313 | AX13: 7724807 | AY13: 7655860 | AZ13: 8472170 | BA13: 7594550 | BB13: 8659640 | BC13: 10786670 | BD13: 9156890 | BE13: 7990770 | BF13: 8240630 | BG13: 8934490 | BH13: 8500470 | BI13: 7150610 | BJ13: 7349390 | BK13: 7285540 | BL13: 8239170 | BM13: 6679240
A14: 신규 | B14: S247533 | C14: S-파스타픽(대) | D14: 0 | E14: 0 | F14: 0 | G14: 0 | H14: 0 | I14: 0 | J14: 0 | K14: 0 | L14: 0 | M14: 0 | N14: 0 | O14: 0 | P14: 0 | Q14: 0 | R14: 0 | S14: 0 | T14: 0 | U14: 0 | V14: 0 | W14: 0 | X14: 0 | Y14: 0 | Z14: 0 | AA14: 0 | AB14: 0 | AC14: 0 | AD14: 0 | AE14: 0 | AF14: 0 | AG14: 0 | AH14: 0 | AI14: 141590 | AJ14: 358300 | AK14: 0 | AL14: 319220 | AM14: 0 | AN14: 527260 | AO14: 164880 | AP14: -17750 | AQ14: 0 | AR14: 2064600 | AS14: 0 | AT14: 0 | AU14: 0 | AV14: 0 | AW14: 0 | AX14: 0 | AY14: 0 | AZ14: 0 | BA14: 0 | BB14: 0 | BC14: 0 | BD14: 0 | BE14: 0 | BF14: 0 | BG14: 0 | BH14: 0 | BI14: 0 | BJ14: 0 | BK14: 0 | BL14: 0 | BM14: 0
A15: 신규 | B15: S248258 | C15: 알쭈 대분류 | D15: 18 | E15: 0 | F15: 0 | G15: 0 | H15: 0 | I15: 0 | J15: 0 | K15: 0 | L15: 0 | M15: 0 | N15: 0 | O15: 0 | P15: 0 | Q15: 0 | R15: 0 | S15: 0 | T15: 0 | U15: 0 | V15: 0 | W15: 0 | X15: 0 | Y15: 0 | Z15: 0 | AA15: 0 | AB15: 0 | AC15: 0 | AD15: 0 | AE15: 0 | AF15: 0 | AG15: 0 | AH15: 0 | AI15: 0 | AJ15: 0 | AK15: 4609550 | AL15: 9799560 | AM15: 8698920 | AN15: 7779520 | AO15: 11063200 | AP15: 6126940 | AQ15: 9059410 | AR15: 7936060 | AS15: 9588980 | AT15: 8225680 | AU15: 7959300 | AV15: 10121890 | AW15: 8747130 | AX15: 10157290 | AY15: 9068230 | AZ15: 6648580 | BA15: 9765960 | BB15: 8204410 | BC15: 8519430 | BD15: 9921330 | BE15: 7446210 | BF15: 8396660 | BG15: 11119080 | BH15: 9160250 | BI15: 10681340 | BJ15: 7872130 | BK15: 8787460 | BL15: 11278350 | BM15: 11481230
A16: 신규 | B16: S249566 | C16: 더라프 대코드 | D16: 28 | E16: 0 | F16: 0 | G16: 0 | H16: 0 | I16: 0 | J16: 0 | K16: 0 | L16: 0 | M16: 0 | N16: 0 | O16: 0 | P16: 0 | Q16: 0 | R16: 0 | S16: 0 | T16: 0 | U16: 0 | V16: 0 | W16: 0 | X16: 0 | Y16: 0 | Z16: 0 | AA16: 0 | AB16: 0 | AC16: 0 | AD16: 0 | AE16: 0 | AF16: 0 | AG16: 0 | AH16: 0 | AI16: 0 | AJ16: 0 | AK16: 13827270 | AL16: 20157565 | AM16: 17493905 | AN16: 19621757 | AO16: 16098803 | AP16: 18751192 | AQ16: 16693631 | AR16: 20486792 | AS16: 17482340 | AT16: 22416783 | AU16: 20345732 | AV16: 18263818 | AW16: 15546953 | AX16: 19499209 | AY16: 18326283 | AZ16: 18173600 | BA16: 18956720 | BB16: 17308850 | BC16: 18351754 | BD16: 18107629 | BE16: 16753154 | BF16: 17694706 | BG16: 17024423 | BH16: 16156233 | BI16: 19544259 | BJ16: 19139522 | BK16: 15461097 | BL16: 18285388 | BM16: 18249773
A17: 신규 | B17: S249140 | C17: 투고샐러드 대 | D17: 5 | E17: 0 | F17: 0 | G17: 0 | H17: 0 | I17: 0 | J17: 0 | K17: 0 | L17: 0 | M17: 0 | N17: 0 | O17: 0 | P17: 0 | Q17: 0 | R17: 0 | S17: 0 | T17: 0 | U17: 0 | V17: 0 | W17: 0 | X17: 0 | Y17: 0 | Z17: 0 | AA17: 0 | AB17: 0 | AC17: 0 | AD17: 0 | AE17: 0 | AF17: 0 | AG17: 0 | AH17: 0 | AI17: 0 | AJ17: 0 | AK17: 0 | AL17: 3851730 | AM17: 9583748 | AN17: 8510107 | AO17: 5618248 | AP17: 5851850 | AQ17: 8024573 | AR17: 8022314 | AS17: 7423445 | AT17: 7825625 | AU17: 7569505 | AV17: 8012205 | AW17: 5919610 | AX17: 6212795 | AY17: 6891782 | AZ17: 5487522 | BA17: 4683450 | BB17: 5315792 | BC17: 4363895 | BD17: 4365605 | BE17: 3888794 | BF17: 4390087 | BG17: 4639852 | BH17: 4535940 | BI17: 4527780 | BJ17: 3265790 | BK17: 3670470 | BL17: 2474440 | BM17: 3406305
... A125: 기존 | B125: S84927 | C125: 스마트푸드네트웍스_FC | D125: 1 | E125: 253154 | F125: -595530 | G125: 98100 | H125: 54430 | I125: 141017 | J125: 48646 | K125: -342193 | L125: 0 | M125: 360691 | N125: 44165 | O125: 14020 | P125: 724575 | Q125: 94035 | R125: 287503 | S125: 51090 | T125: 377925 | U125: 168647 | V125: 0 | W125: 120210 | X125: -334038 | Y125: 88200 | Z125: 254200 | AA125: 163319 | AB125: 152125 | AC125: 63050 | AD125: 235938 | AE125: 0 | AF125: 493756 | AG125: 92830 | AH125: 209175 | AI125: 139757 | AJ125: 135530 | AK125: -497153 | AL125: 493678 | AM125: 57170 | AN125: 128481 | AO125: 38680 | AP125: 186961 | AQ125: 6800 | AR125: 135571 | AS125: -329332 | AT125: 96600 | AU125: 206477 | AV125: 374421 | AW125: 229705 | AX125: -820263 | AY125: 251516 | AZ125: 175499 | BA125: 628993 | BB125: 118035 | BC125: 196380 | BD125: 203172 | BE125: 249830 | BF125: 189710 | BG125: -839092 | BH125: 86675 | BI125: 21990 | BJ125: 52869 | BK125: -83344 | BL125: 46800 | BM125: 144780

Sheet 월별 매출
A1: 걸개처별 월간 매출 (원) — 출처: Monthly Brand Tracking 시트 [매출]
A3: 구분 | B3: 본점코드 | C3: 본점명 | D3: 월 매출 (원) | N3: 전월 대비 증감률
D4: 1월 | E4: 2월 | F4: 3월 | G4: 4월 | H4: 5월 | I4: 6월 | J4: 7월 | K4: 8월 | L4: 9월 | M4: 1~9월 누계 | N4: 2월 | O4: 3월 | P4: 4월 | Q4: 5월 | R4: 6월 | S4: 7월 | T4: 8월 | U4: 9월
A5: 합계 | D5: =SUM(D6:D125) -> 21750286263 | E5: =SUM(E6:E125) -> 19295447144 | F5: =SUM(F6:F125) -> 20923415382 | G5: =SUM(G6:G125) -> 21599349179 | H5: =SUM(H6:H125) -> 23431970830 | I5: =SUM(I6:I125) -> 22333222631 | J5: =SUM(J6:J125) -> 23465564667 | K5: =SUM(K6:K125) -> 22767166005 | L5: =SUM(L6:L125) -> 21340213998 | M5: =SUM(D5:L5) -> 196906636099 | N5: =IF(D5=0,"",E5/D5-1) -> -0.11286468 | O5: =IF(E5=0,"",F5/E5-1) -> 0.084370589 | P5: =IF(F5=0,"",G5/F5-1) -> 0.032305137 | Q5: =IF(G5=0,"",H5/G5-1) -> 0.084846151 | R5: =IF(H5=0,"",I5/H5-1) -> -0.046890985 | S5: =IF(I5=0,"",J5/I5-1) -> 0.050702134 | T5: =IF(J5=0,"",K5/J5-1) -> -0.029762704 | U5: =IF(K5=0,"",L5/K5-1) -> -0.062675873
A6: 신규 | B6: S240084 | C6: 찌개찝 대 | D6: 28701402 | E6: 27821580 | F6: 28353960 | G6: 28346830 | H6: 26403290 | I6: 25544410 | J6: 22296220 | K6: 18766180 | L6: 18149340 | M6: =SUM(D6:L6) -> 224383212 | N6: =IF(D6=0,"",E6/D6-1) -> -0.030654321 | O6: =IF(E6=0,"",F6/E6-1) -> 0.019135506 | P6: =IF(F6=0,"",G6/F6-1) -> -0.00025146399 | Q6: =IF(G6=0,"",H6/G6-1) -> -0.068562869 | R6: =IF(H6=0,"",I6/H6-1) -> -0.032529279 | S6: =IF(I6=0,"",J6/I6-1) -> -0.12715854 | T6: =IF(J6=0,"",K6/J6-1) -> -0.15832459 | U6: =IF(K6=0,"",L6/K6-1) -> -0.032869769
A7: 신규 | B7: S243775 | C7: 비어프랜드 대 | D7: 0 | E7: 30965320 | F7: 29274310 | G7: 32053920 | H7: 34688730 | I7: 32356980 | J7: 32916450 | K7: 25711290 | L7: 23634020 | M7: =SUM(D7:L7) -> 241601020 | N7: =IF(D7=0,"",E7/D7-1) | O7: =IF(E7=0,"",F7/E7-1) -> -0.054609802 | P7: =IF(F7=0,"",G7/F7-1) -> 0.094950487 | Q7: =IF(G7=0,"",H7/G7-1) -> 0.082199307 | R7: =IF(H7=0,"",I7/H7-1) -> -0.067219238 | S7: =IF(I7=0,"",J7/I7-1) -> 0.017290551 | T7: =IF(J7=0,"",K7/J7-1) -> -0.21889238 | U7: =IF(K7=0,"",L7/K7-1) -> -0.080792135
A8: 신규 | B8: S242492 | C8: 카페차이(대) | D8: 1160912 | E8: 13037856 | F8: 10651352 | G8: 18772924 | H8: 12651485 | I8: 10098495 | J8: 9991242 | K8: 9920770 | L8: 11103634 | M8: =SUM(D8:L8) -> 97388670 | N8: =IF(D8=0,"",E8/D8-1) -> 10.230701 | O8: =IF(E8=0,"",F8/E8-1) -> -0.18304421 | P8: =IF(F8=0,"",G8/F8-1) -> 0.76249212 | Q8: =IF(G8=0,"",H8/G8-1) -> -0.32607808 | R8: =IF(H8=0,"",I8/H8-1) -> -0.2017937 | S8: =IF(I8=0,"",J8/I8-1) -> -0.010620691 | T8: =IF(J8=0,"",K8/J8-1) -> -0.0070533773 | U8: =IF(K8=0,"",L8/K8-1) -> 0.11923107
